2018-03-17 08:17:24 WARNING (Recorder) [homeassistant.components.recorder] Ended unfinished session (id=1 from 2018-03-16 18:24:02.767718)
2018-03-17 08:17:36 WARNING (MainThread) [homeassistant.components.sensor] Setup of platform yr is taking over 10 seconds.
2018-03-17 08:17:36 ERROR (MainThread) [homeassistant.components.sensor.yr] Retrying in 18 minutes: 
2018-03-17 08:17:46 ERROR (MainThread) [homeassistant.components.cloud] Error fetching Cognito keyset: 
2018-03-17 14:19:16 WARNING (MainThread) [homeassistant.helpers.entity] Update of media_player.roku_2la4d5015997 is taking over 10 seconds
2018-03-17 14:19:17 WARNING (MainThread) [homeassistant.components.media_player] Updating roku media_player took longer than the scheduled update interval 0:00:10
2018-03-17 14:19:28 WARNING (MainThread) [homeassistant.components.media_player] Updating roku media_player took longer than the scheduled update interval 0:00:10
2018-03-17 14:19:39 WARNING (MainThread) [homeassistant.components.media_player] Updating roku media_player took longer than the scheduled update interval 0:00:10
2018-03-17 14:19:50 WARNING (MainThread) [homeassistant.components.media_player] Updating roku media_player took longer than the scheduled update interval 0:00:10
2018-03-17 14:20:01 WARNING (MainThread) [homeassistant.components.media_player] Updating roku media_player took longer than the scheduled update interval 0:00:10
2018-03-17 14:20:12 WARNING (MainThread) [homeassistant.components.media_player] Updating roku media_player took longer than the scheduled update interval 0:00:10
2018-03-17 14:20:23 WARNING (MainThread) [homeassistant.components.media_player] Updating roku media_player took longer than the scheduled update interval 0:00:10
2018-03-17 14:20:34 WARNING (MainThread) [homeassistant.components.media_player] Updating roku media_player took longer than the scheduled update interval 0:00:10
2018-03-17 14:20:45 WARNING (MainThread) [homeassistant.components.media_player] Updating roku media_player took longer than the scheduled update interval 0:00:10
2018-03-17 14:20:56 WARNING (MainThread) [homeassistant.components.media_player] Updating roku media_player took longer than the scheduled update interval 0:00:10
2018-03-17 14:21:07 WARNING (MainThread) [homeassistant.components.media_player] Updating roku media_player took longer than the scheduled update interval 0:00:10
2018-03-17 14:21:18 WARNING (MainThread) [homeassistant.components.media_player] Updating roku media_player took longer than the scheduled update interval 0:00:10
2018-03-17 17:42:25 WARNING (MainThread) [homeassistant.helpers.entity] Update of media_player.roku_2la4d5015997 is taking over 10 seconds
2018-03-17 17:42:26 WARNING (MainThread) [homeassistant.components.media_player] Updating roku media_player took longer than the scheduled update interval 0:00:10
2018-03-17 17:42:37 WARNING (MainThread) [homeassistant.components.media_player] Updating roku media_player took longer than the scheduled update interval 0:00:10
2018-03-17 18:18:17 WARNING (Thread-15) [netdisco.ssdp] Found malformed XML at http://192.168.1.193:9080: status=ok
2018-03-17 18:39:51 WARNING (MainThread) [homeassistant.helpers.entity] Update of media_player.roku_2la4d5015997 is taking over 10 seconds
2018-03-17 18:39:52 WARNING (MainThread) [homeassistant.components.media_player] Updating roku media_player took longer than the scheduled update interval 0:00:10
2018-03-17 18:40:03 WARNING (MainThread) [homeassistant.components.media_player] Updating roku media_player took longer than the scheduled update interval 0:00:10
2018-03-17 18:40:14 WARNING (MainThread) [homeassistant.components.media_player] Updating roku media_player took longer than the scheduled update interval 0:00:10
2018-03-17 18:40:25 WARNING (MainThread) [homeassistant.components.media_player] Updating roku media_player took longer than the scheduled update interval 0:00:10
2018-03-17 18:40:36 WARNING (MainThread) [homeassistant.components.media_player] Updating roku media_player took longer than the scheduled update interval 0:00:10
2018-03-17 18:40:47 WARNING (MainThread) [homeassistant.components.media_player] Updating roku media_player took longer than the scheduled update interval 0:00:10
2018-03-17 18:40:58 WARNING (MainThread) [homeassistant.components.media_player] Updating roku media_player took longer than the scheduled update interval 0:00:10
2018-03-17 18:41:09 WARNING (MainThread) [homeassistant.components.media_player] Updating roku media_player took longer than the scheduled update interval 0:00:10
2018-03-17 18:41:20 WARNING (MainThread) [homeassistant.components.media_player] Updating roku media_player took longer than the scheduled update interval 0:00:10
2018-03-17 18:41:31 WARNING (MainThread) [homeassistant.components.media_player] Updating roku media_player took longer than the scheduled update interval 0:00:10
2018-03-17 18:41:42 WARNING (MainThread) [homeassistant.components.media_player] Updating roku media_player took longer than the scheduled update interval 0:00:10
2018-03-17 18:41:53 WARNING (MainThread) [homeassistant.components.media_player] Updating roku media_player took longer than the scheduled update interval 0:00:10
2018-03-17 18:42:04 WARNING (MainThread) [homeassistant.components.media_player] Updating roku media_player took longer than the scheduled update interval 0:00:10
2018-03-17 18:42:15 WARNING (MainThread) [homeassistant.components.media_player] Updating roku media_player took longer than the scheduled update interval 0:00:10
2018-03-17 18:42:26 WARNING (MainThread) [homeassistant.components.media_player] Updating roku media_player took longer than the scheduled update interval 0:00:10
2018-03-17 18:42:37 WARNING (MainThread) [homeassistant.components.media_player] Updating roku media_player took longer than the scheduled update interval 0:00:10
2018-03-17 18:42:48 WARNING (MainThread) [homeassistant.components.media_player] Updating roku media_player took longer than the scheduled update interval 0:00:10
2018-03-17 18:42:59 WARNING (MainThread) [homeassistant.components.media_player] Updating roku media_player took longer than the scheduled update interval 0:00:10
2018-03-17 18:43:10 WARNING (MainThread) [homeassistant.components.media_player] Updating roku media_player took longer than the scheduled update interval 0:00:10
2018-03-17 18:43:21 WARNING (MainThread) [homeassistant.components.media_player] Updating roku media_player took longer than the scheduled update interval 0:00:10
2018-03-17 18:43:31 WARNING (MainThread) [homeassistant.components.media_player] Updating roku media_player took longer than the scheduled update interval 0:00:10
2018-03-17 18:43:42 WARNING (MainThread) [homeassistant.components.media_player] Updating roku media_player took longer than the scheduled update interval 0:00:10
2018-03-17 18:43:53 WARNING (MainThread) [homeassistant.components.media_player] Updating roku media_player took longer than the scheduled update interval 0:00:10
2018-03-17 18:44:04 WARNING (MainThread) [homeassistant.components.media_player] Updating roku media_player took longer than the scheduled update interval 0:00:10
2018-03-17 18:44:15 WARNING (MainThread) [homeassistant.components.media_player] Updating roku media_player took longer than the scheduled update interval 0:00:10
2018-03-17 18:44:26 WARNING (MainThread) [homeassistant.components.media_player] Updating roku media_player took longer than the scheduled update interval 0:00:10
2018-03-17 18:44:37 WARNING (MainThread) [homeassistant.components.media_player] Updating roku media_player took longer than the scheduled update interval 0:00:10
2018-03-17 18:44:48 WARNING (MainThread) [homeassistant.components.media_player] Updating roku media_player took longer than the scheduled update interval 0:00:10
2018-03-17 18:44:59 WARNING (MainThread) [homeassistant.components.media_player] Updating roku media_player took longer than the scheduled update interval 0:00:10
2018-03-17 18:45:10 WARNING (MainThread) [homeassistant.components.media_player] Updating roku media_player took longer than the scheduled update interval 0:00:10
2018-03-17 18:45:21 WARNING (MainThread) [homeassistant.components.media_player] Updating roku media_player took longer than the scheduled update interval 0:00:10
2018-03-17 18:45:31 WARNING (MainThread) [homeassistant.components.media_player] Updating roku media_player took longer than the scheduled update interval 0:00:10
2018-03-17 18:45:42 WARNING (MainThread) [homeassistant.components.media_player] Updating roku media_player took longer than the scheduled update interval 0:00:10
2018-03-17 18:45:53 WARNING (MainThread) [homeassistant.components.media_player] Updating roku media_player took longer than the scheduled update interval 0:00:10
2018-03-17 18:46:04 WARNING (MainThread) [homeassistant.components.media_player] Updating roku media_player took longer than the scheduled update interval 0:00:10
2018-03-17 18:46:15 WARNING (MainThread) [homeassistant.components.media_player] Updating roku media_player took longer than the scheduled update interval 0:00:10
2018-03-17 18:46:26 WARNING (MainThread) [homeassistant.components.media_player] Updating roku media_player took longer than the scheduled update interval 0:00:10
2018-03-17 18:46:37 WARNING (MainThread) [homeassistant.components.media_player] Updating roku media_player took longer than the scheduled update interval 0:00:10
2018-03-17 18:46:48 WARNING (MainThread) [homeassistant.components.media_player] Updating roku media_player took longer than the scheduled update interval 0:00:10
2018-03-17 18:46:59 WARNING (MainThread) [homeassistant.components.media_player] Updating roku media_player took longer than the scheduled update interval 0:00:10
2018-03-17 18:47:10 WARNING (MainThread) [homeassistant.components.media_player] Updating roku media_player took longer than the scheduled update interval 0:00:10
2018-03-17 18:47:21 WARNING (MainThread) [homeassistant.components.media_player] Updating roku media_player took longer than the scheduled update interval 0:00:10
2018-03-17 18:47:31 WARNING (MainThread) [homeassistant.components.media_player] Updating roku media_player took longer than the scheduled update interval 0:00:10
2018-03-17 18:47:42 WARNING (MainThread) [homeassistant.components.media_player] Updating roku media_player took longer than the scheduled update interval 0:00:10
2018-03-17 18:47:53 WARNING (MainThread) [homeassistant.components.media_player] Updating roku media_player took longer than the scheduled update interval 0:00:10
2018-03-17 18:48:04 WARNING (MainThread) [homeassistant.components.media_player] Updating roku media_player took longer than the scheduled update interval 0:00:10
2018-03-17 18:48:15 WARNING (MainThread) [homeassistant.components.media_player] Updating roku media_player took longer than the scheduled update interval 0:00:10
2018-03-17 18:48:26 WARNING (MainThread) [homeassistant.components.media_player] Updating roku media_player took longer than the scheduled update interval 0:00:10
2018-03-17 18:48:37 WARNING (MainThread) [homeassistant.components.media_player] Updating roku media_player took longer than the scheduled update interval 0:00:10
2018-03-17 18:48:48 WARNING (MainThread) [homeassistant.components.media_player] Updating roku media_player took longer than the scheduled update interval 0:00:10
2018-03-17 18:48:59 WARNING (MainThread) [homeassistant.components.media_player] Updating roku media_player took longer than the scheduled update interval 0:00:10
2018-03-17 18:49:10 WARNING (MainThread) [homeassistant.components.media_player] Updating roku media_player took longer than the scheduled update interval 0:00:10
2018-03-17 18:49:21 WARNING (MainThread) [homeassistant.components.media_player] Updating roku media_player took longer than the scheduled update interval 0:00:10
2018-03-17 18:49:32 WARNING (MainThread) [homeassistant.components.media_player] Updating roku media_player took longer than the scheduled update interval 0:00:10
2018-03-17 18:49:43 WARNING (MainThread) [homeassistant.components.media_player] Updating roku media_player took longer than the scheduled update interval 0:00:10
2018-03-17 18:49:54 WARNING (MainThread) [homeassistant.components.media_player] Updating roku media_player took longer than the scheduled update interval 0:00:10
2018-03-17 18:50:05 WARNING (MainThread) [homeassistant.components.media_player] Updating roku media_player took longer than the scheduled update interval 0:00:10
2018-03-17 18:50:16 WARNING (MainThread) [homeassistant.components.media_player] Updating roku media_player took longer than the scheduled update interval 0:00:10
2018-03-17 18:50:27 WARNING (MainThread) [homeassistant.components.media_player] Updating roku media_player took longer than the scheduled update interval 0:00:10
2018-03-17 18:50:38 WARNING (MainThread) [homeassistant.components.media_player] Updating roku media_player took longer than the scheduled update interval 0:00:10
2018-03-17 18:50:49 WARNING (MainThread) [homeassistant.components.media_player] Updating roku media_player took longer than the scheduled update interval 0:00:10
2018-03-17 18:51:00 WARNING (MainThread) [homeassistant.components.media_player] Updating roku media_player took longer than the scheduled update interval 0:00:10
2018-03-17 18:51:11 WARNING (MainThread) [homeassistant.components.media_player] Updating roku media_player took longer than the scheduled update interval 0:00:10
2018-03-17 18:51:22 WARNING (MainThread) [homeassistant.components.media_player] Updating roku media_player took longer than the scheduled update interval 0:00:10
2018-03-17 18:51:33 WARNING (MainThread) [homeassistant.components.media_player] Updating roku media_player took longer than the scheduled update interval 0:00:10
2018-03-17 18:51:44 WARNING (MainThread) [homeassistant.components.media_player] Updating roku media_player took longer than the scheduled update interval 0:00:10
2018-03-17 18:51:55 WARNING (MainThread) [homeassistant.components.media_player] Updating roku media_player took longer than the scheduled update interval 0:00:10
2018-03-17 18:52:06 WARNING (MainThread) [homeassistant.components.media_player] Updating roku media_player took longer than the scheduled update interval 0:00:10
2018-03-17 18:52:17 WARNING (MainThread) [homeassistant.components.media_player] Updating roku media_player took longer than the scheduled update interval 0:00:10
2018-03-17 18:52:28 WARNING (MainThread) [homeassistant.components.media_player] Updating roku media_player took longer than the scheduled update interval 0:00:10
2018-03-17 18:52:39 WARNING (MainThread) [homeassistant.components.media_player] Updating roku media_player took longer than the scheduled update interval 0:00:10
2018-03-17 18:52:50 WARNING (MainThread) [homeassistant.components.media_player] Updating roku media_player took longer than the scheduled update interval 0:00:10
2018-03-17 18:53:01 WARNING (MainThread) [homeassistant.components.media_player] Updating roku media_player took longer than the scheduled update interval 0:00:10
2018-03-17 18:53:12 WARNING (MainThread) [homeassistant.components.media_player] Updating roku media_player took longer than the scheduled update interval 0:00:10
2018-03-17 18:53:23 WARNING (MainThread) [homeassistant.components.media_player] Updating roku media_player took longer than the scheduled update interval 0:00:10
2018-03-17 18:53:34 WARNING (MainThread) [homeassistant.components.media_player] Updating roku media_player took longer than the scheduled update interval 0:00:10
2018-03-17 18:53:45 WARNING (MainThread) [homeassistant.components.media_player] Updating roku media_player took longer than the scheduled update interval 0:00:10
2018-03-17 18:53:56 WARNING (MainThread) [homeassistant.components.media_player] Updating roku media_player took longer than the scheduled update interval 0:00:10
2018-03-17 18:54:07 WARNING (MainThread) [homeassistant.components.media_player] Updating roku media_player took longer than the scheduled update interval 0:00:10
2018-03-17 18:54:18 WARNING (MainThread) [homeassistant.components.media_player] Updating roku media_player took longer than the scheduled update interval 0:00:10
2018-03-17 18:54:29 WARNING (MainThread) [homeassistant.components.media_player] Updating roku media_player took longer than the scheduled update interval 0:00:10
2018-03-17 18:54:40 WARNING (MainThread) [homeassistant.components.media_player] Updating roku media_player took longer than the scheduled update interval 0:00:10
2018-03-17 18:54:51 WARNING (MainThread) [homeassistant.components.media_player] Updating roku media_player took longer than the scheduled update interval 0:00:10
2018-03-17 18:55:02 WARNING (MainThread) [homeassistant.components.media_player] Updating roku media_player took longer than the scheduled update interval 0:00:10
2018-03-17 18:55:13 WARNING (MainThread) [homeassistant.components.media_player] Updating roku media_player took longer than the scheduled update interval 0:00:10
2018-03-18 09:49:35 ERROR (MainThread) [aiohttp.server] Error handling request
Traceback (most recent call last):
  File "/srv/homeassistant/lib/python3.5/site-packages/aiohttp/connector.py", line 800, in _wrap_create_connection
    return await self._loop.create_connection(*args, **kwargs)
  File "/usr/lib/python3.5/asyncio/base_events.py", line 775, in create_connection
    raise exceptions[0]
  File "/usr/lib/python3.5/asyncio/base_events.py", line 762, in create_connection
    yield from self.sock_connect(sock, address)
  File "/usr/lib/python3.5/asyncio/selector_events.py", line 451, in sock_connect
    return (yield from fut)
  File "/usr/lib/python3.5/asyncio/futures.py", line 380, in __iter__
    yield self  # This tells Task to wait for completion.
  File "/usr/lib/python3.5/asyncio/tasks.py", line 304, in _wakeup
    future.result()
  File "/usr/lib/python3.5/asyncio/futures.py", line 293, in result
    raise self._exception
  File "/usr/lib/python3.5/asyncio/selector_events.py", line 481, in _sock_connect_cb
    raise OSError(err, 'Connect call failed %s' % (address,))
OSError: [Errno 113] Connect call failed ('192.168.1.193', 8060)

The above exception was the direct cause of the following exception:

Traceback (most recent call last):
  File "/srv/homeassistant/lib/python3.5/site-packages/aiohttp/web_protocol.py", line 381, in start
    resp = await self._request_handler(request)
  File "/srv/homeassistant/lib/python3.5/site-packages/aiohttp/web_app.py", line 310, in _handle
    resp = await handler(request)
  File "/srv/homeassistant/lib/python3.5/site-packages/aiohttp/web_middlewares.py", line 88, in impl
    return await handler(request)
  File "/srv/homeassistant/lib/python3.5/site-packages/homeassistant/components/http/static.py", line 68, in staticresource_middleware
    return await handler(request)
  File "/srv/homeassistant/lib/python3.5/site-packages/homeassistant/components/http/real_ip.py", line 27, in real_ip_middleware
    return await handler(request)
  File "/srv/homeassistant/lib/python3.5/site-packages/homeassistant/components/http/ban.py", line 68, in ban_middleware
    return await handler(request)
  File "/srv/homeassistant/lib/python3.5/site-packages/homeassistant/components/http/auth.py", line 28, in auth_middleware
    return await handler(request)
  File "/srv/homeassistant/lib/python3.5/site-packages/homeassistant/components/http/view.py", line 100, in handle
    result = await result
  File "/srv/homeassistant/lib/python3.5/site-packages/homeassistant/components/media_player/__init__.py", line 944, in get
    data, content_type = yield from player.async_get_media_image()
  File "/srv/homeassistant/lib/python3.5/site-packages/homeassistant/components/media_player/__init__.py", line 499, in async_get_media_image
    return (yield from _async_fetch_image(self.hass, url))
  File "/srv/homeassistant/lib/python3.5/site-packages/homeassistant/components/media_player/__init__.py", line 901, in _async_fetch_image
    response = yield from websession.get(url)
  File "/srv/homeassistant/lib/python3.5/site-packages/aiohttp/client.py", line 319, in _request
    traces=traces
  File "/srv/homeassistant/lib/python3.5/site-packages/aiohttp/connector.py", line 418, in connect
    traces=traces
  File "/srv/homeassistant/lib/python3.5/site-packages/aiohttp/connector.py", line 736, in _create_connection
    traces=None
  File "/srv/homeassistant/lib/python3.5/site-packages/aiohttp/connector.py", line 855, in _create_direct_connection
    raise last_exc
  File "/srv/homeassistant/lib/python3.5/site-packages/aiohttp/connector.py", line 838, in _create_direct_connection
    req=req, client_error=client_error)
  File "/srv/homeassistant/lib/python3.5/site-packages/aiohttp/connector.py", line 807, in _wrap_create_connection
    raise client_error(req.connection_key, exc) from exc
aiohttp.client_exceptions.ClientConnectorError: Cannot connect to host 192.168.1.193:8060 ssl:False [Connect call failed ('192.168.1.193', 8060)]
2018-03-18 09:50:33 ERROR (MainThread) [aiohttp.server] Error handling request
Traceback (most recent call last):
  File "/srv/homeassistant/lib/python3.5/site-packages/aiohttp/connector.py", line 800, in _wrap_create_connection
    return await self._loop.create_connection(*args, **kwargs)
  File "/usr/lib/python3.5/asyncio/base_events.py", line 775, in create_connection
    raise exceptions[0]
  File "/usr/lib/python3.5/asyncio/base_events.py", line 762, in create_connection
    yield from self.sock_connect(sock, address)
  File "/usr/lib/python3.5/asyncio/selector_events.py", line 451, in sock_connect
    return (yield from fut)
  File "/usr/lib/python3.5/asyncio/futures.py", line 380, in __iter__
    yield self  # This tells Task to wait for completion.
  File "/usr/lib/python3.5/asyncio/tasks.py", line 304, in _wakeup
    future.result()
  File "/usr/lib/python3.5/asyncio/futures.py", line 293, in result
    raise self._exception
  File "/usr/lib/python3.5/asyncio/selector_events.py", line 481, in _sock_connect_cb
    raise OSError(err, 'Connect call failed %s' % (address,))
OSError: [Errno 113] Connect call failed ('192.168.1.193', 8060)

The above exception was the direct cause of the following exception:

Traceback (most recent call last):
  File "/srv/homeassistant/lib/python3.5/site-packages/aiohttp/web_protocol.py", line 381, in start
    resp = await self._request_handler(request)
  File "/srv/homeassistant/lib/python3.5/site-packages/aiohttp/web_app.py", line 310, in _handle
    resp = await handler(request)
  File "/srv/homeassistant/lib/python3.5/site-packages/aiohttp/web_middlewares.py", line 88, in impl
    return await handler(request)
  File "/srv/homeassistant/lib/python3.5/site-packages/homeassistant/components/http/static.py", line 68, in staticresource_middleware
    return await handler(request)
  File "/srv/homeassistant/lib/python3.5/site-packages/homeassistant/components/http/real_ip.py", line 27, in real_ip_middleware
    return await handler(request)
  File "/srv/homeassistant/lib/python3.5/site-packages/homeassistant/components/http/ban.py", line 68, in ban_middleware
    return await handler(request)
  File "/srv/homeassistant/lib/python3.5/site-packages/homeassistant/components/http/auth.py", line 28, in auth_middleware
    return await handler(request)
  File "/srv/homeassistant/lib/python3.5/site-packages/homeassistant/components/http/view.py", line 100, in handle
    result = await result
  File "/srv/homeassistant/lib/python3.5/site-packages/homeassistant/components/media_player/__init__.py", line 944, in get
    data, content_type = yield from player.async_get_media_image()
  File "/srv/homeassistant/lib/python3.5/site-packages/homeassistant/components/media_player/__init__.py", line 499, in async_get_media_image
    return (yield from _async_fetch_image(self.hass, url))
  File "/srv/homeassistant/lib/python3.5/site-packages/homeassistant/components/media_player/__init__.py", line 901, in _async_fetch_image
    response = yield from websession.get(url)
  File "/srv/homeassistant/lib/python3.5/site-packages/aiohttp/client.py", line 319, in _request
    traces=traces
  File "/srv/homeassistant/lib/python3.5/site-packages/aiohttp/connector.py", line 418, in connect
    traces=traces
  File "/srv/homeassistant/lib/python3.5/site-packages/aiohttp/connector.py", line 736, in _create_connection
    traces=None
  File "/srv/homeassistant/lib/python3.5/site-packages/aiohttp/connector.py", line 855, in _create_direct_connection
    raise last_exc
  File "/srv/homeassistant/lib/python3.5/site-packages/aiohttp/connector.py", line 838, in _create_direct_connection
    req=req, client_error=client_error)
  File "/srv/homeassistant/lib/python3.5/site-packages/aiohttp/connector.py", line 807, in _wrap_create_connection
    raise client_error(req.connection_key, exc) from exc
aiohttp.client_exceptions.ClientConnectorError: Cannot connect to host 192.168.1.193:8060 ssl:False [Connect call failed ('192.168.1.193', 8060)]
2018-03-18 09:52:31 ERROR (MainThread) [aiohttp.server] Error handling request
Traceback (most recent call last):
  File "/srv/homeassistant/lib/python3.5/site-packages/aiohttp/connector.py", line 800, in _wrap_create_connection
    return await self._loop.create_connection(*args, **kwargs)
  File "/usr/lib/python3.5/asyncio/base_events.py", line 775, in create_connection
    raise exceptions[0]
  File "/usr/lib/python3.5/asyncio/base_events.py", line 762, in create_connection
    yield from self.sock_connect(sock, address)
  File "/usr/lib/python3.5/asyncio/selector_events.py", line 451, in sock_connect
    return (yield from fut)
  File "/usr/lib/python3.5/asyncio/futures.py", line 380, in __iter__
    yield self  # This tells Task to wait for completion.
  File "/usr/lib/python3.5/asyncio/tasks.py", line 304, in _wakeup
    future.result()
  File "/usr/lib/python3.5/asyncio/futures.py", line 293, in result
    raise self._exception
  File "/usr/lib/python3.5/asyncio/selector_events.py", line 481, in _sock_connect_cb
    raise OSError(err, 'Connect call failed %s' % (address,))
OSError: [Errno 113] Connect call failed ('192.168.1.193', 8060)

The above exception was the direct cause of the following exception:

Traceback (most recent call last):
  File "/srv/homeassistant/lib/python3.5/site-packages/aiohttp/web_protocol.py", line 381, in start
    resp = await self._request_handler(request)
  File "/srv/homeassistant/lib/python3.5/site-packages/aiohttp/web_app.py", line 310, in _handle
    resp = await handler(request)
  File "/srv/homeassistant/lib/python3.5/site-packages/aiohttp/web_middlewares.py", line 88, in impl
    return await handler(request)
  File "/srv/homeassistant/lib/python3.5/site-packages/homeassistant/components/http/static.py", line 68, in staticresource_middleware
    return await handler(request)
  File "/srv/homeassistant/lib/python3.5/site-packages/homeassistant/components/http/real_ip.py", line 27, in real_ip_middleware
    return await handler(request)
  File "/srv/homeassistant/lib/python3.5/site-packages/homeassistant/components/http/ban.py", line 68, in ban_middleware
    return await handler(request)
  File "/srv/homeassistant/lib/python3.5/site-packages/homeassistant/components/http/auth.py", line 28, in auth_middleware
    return await handler(request)
  File "/srv/homeassistant/lib/python3.5/site-packages/homeassistant/components/http/view.py", line 100, in handle
    result = await result
  File "/srv/homeassistant/lib/python3.5/site-packages/homeassistant/components/media_player/__init__.py", line 944, in get
    data, content_type = yield from player.async_get_media_image()
  File "/srv/homeassistant/lib/python3.5/site-packages/homeassistant/components/media_player/__init__.py", line 499, in async_get_media_image
    return (yield from _async_fetch_image(self.hass, url))
  File "/srv/homeassistant/lib/python3.5/site-packages/homeassistant/components/media_player/__init__.py", line 901, in _async_fetch_image
    response = yield from websession.get(url)
  File "/srv/homeassistant/lib/python3.5/site-packages/aiohttp/client.py", line 319, in _request
    traces=traces
  File "/srv/homeassistant/lib/python3.5/site-packages/aiohttp/connector.py", line 418, in connect
    traces=traces
  File "/srv/homeassistant/lib/python3.5/site-packages/aiohttp/connector.py", line 736, in _create_connection
    traces=None
  File "/srv/homeassistant/lib/python3.5/site-packages/aiohttp/connector.py", line 855, in _create_direct_connection
    raise last_exc
  File "/srv/homeassistant/lib/python3.5/site-packages/aiohttp/connector.py", line 838, in _create_direct_connection
    req=req, client_error=client_error)
  File "/srv/homeassistant/lib/python3.5/site-packages/aiohttp/connector.py", line 807, in _wrap_create_connection
    raise client_error(req.connection_key, exc) from exc
aiohttp.client_exceptions.ClientConnectorError: Cannot connect to host 192.168.1.193:8060 ssl:False [Connect call failed ('192.168.1.193', 8060)]
2018-03-18 09:53:34 ERROR (MainThread) [aiohttp.server] Error handling request
Traceback (most recent call last):
  File "/srv/homeassistant/lib/python3.5/site-packages/aiohttp/connector.py", line 800, in _wrap_create_connection
    return await self._loop.create_connection(*args, **kwargs)
  File "/usr/lib/python3.5/asyncio/base_events.py", line 775, in create_connection
    raise exceptions[0]
  File "/usr/lib/python3.5/asyncio/base_events.py", line 762, in create_connection
    yield from self.sock_connect(sock, address)
  File "/usr/lib/python3.5/asyncio/selector_events.py", line 451, in sock_connect
    return (yield from fut)
  File "/usr/lib/python3.5/asyncio/futures.py", line 380, in __iter__
    yield self  # This tells Task to wait for completion.
  File "/usr/lib/python3.5/asyncio/tasks.py", line 304, in _wakeup
    future.result()
  File "/usr/lib/python3.5/asyncio/futures.py", line 293, in result
    raise self._exception
  File "/usr/lib/python3.5/asyncio/selector_events.py", line 481, in _sock_connect_cb
    raise OSError(err, 'Connect call failed %s' % (address,))
OSError: [Errno 113] Connect call failed ('192.168.1.193', 8060)

The above exception was the direct cause of the following exception:

Traceback (most recent call last):
  File "/srv/homeassistant/lib/python3.5/site-packages/aiohttp/web_protocol.py", line 381, in start
    resp = await self._request_handler(request)
  File "/srv/homeassistant/lib/python3.5/site-packages/aiohttp/web_app.py", line 310, in _handle
    resp = await handler(request)
  File "/srv/homeassistant/lib/python3.5/site-packages/aiohttp/web_middlewares.py", line 88, in impl
    return await handler(request)
  File "/srv/homeassistant/lib/python3.5/site-packages/homeassistant/components/http/static.py", line 68, in staticresource_middleware
    return await handler(request)
  File "/srv/homeassistant/lib/python3.5/site-packages/homeassistant/components/http/real_ip.py", line 27, in real_ip_middleware
    return await handler(request)
  File "/srv/homeassistant/lib/python3.5/site-packages/homeassistant/components/http/ban.py", line 68, in ban_middleware
    return await handler(request)
  File "/srv/homeassistant/lib/python3.5/site-packages/homeassistant/components/http/auth.py", line 28, in auth_middleware
    return await handler(request)
  File "/srv/homeassistant/lib/python3.5/site-packages/homeassistant/components/http/view.py", line 100, in handle
    result = await result
  File "/srv/homeassistant/lib/python3.5/site-packages/homeassistant/components/media_player/__init__.py", line 944, in get
    data, content_type = yield from player.async_get_media_image()
  File "/srv/homeassistant/lib/python3.5/site-packages/homeassistant/components/media_player/__init__.py", line 499, in async_get_media_image
    return (yield from _async_fetch_image(self.hass, url))
  File "/srv/homeassistant/lib/python3.5/site-packages/homeassistant/components/media_player/__init__.py", line 901, in _async_fetch_image
    response = yield from websession.get(url)
  File "/srv/homeassistant/lib/python3.5/site-packages/aiohttp/client.py", line 319, in _request
    traces=traces
  File "/srv/homeassistant/lib/python3.5/site-packages/aiohttp/connector.py", line 418, in connect
    traces=traces
  File "/srv/homeassistant/lib/python3.5/site-packages/aiohttp/connector.py", line 736, in _create_connection
    traces=None
  File "/srv/homeassistant/lib/python3.5/site-packages/aiohttp/connector.py", line 855, in _create_direct_connection
    raise last_exc
  File "/srv/homeassistant/lib/python3.5/site-packages/aiohttp/connector.py", line 838, in _create_direct_connection
    req=req, client_error=client_error)
  File "/srv/homeassistant/lib/python3.5/site-packages/aiohttp/connector.py", line 807, in _wrap_create_connection
    raise client_error(req.connection_key, exc) from exc
aiohttp.client_exceptions.ClientConnectorError: Cannot connect to host 192.168.1.193:8060 ssl:False [Connect call failed ('192.168.1.193', 8060)]
2018-03-18 09:54:32 ERROR (MainThread) [aiohttp.server] Error handling request
Traceback (most recent call last):
  File "/srv/homeassistant/lib/python3.5/site-packages/aiohttp/connector.py", line 800, in _wrap_create_connection
    return await self._loop.create_connection(*args, **kwargs)
  File "/usr/lib/python3.5/asyncio/base_events.py", line 775, in create_connection
    raise exceptions[0]
  File "/usr/lib/python3.5/asyncio/base_events.py", line 762, in create_connection
    yield from self.sock_connect(sock, address)
  File "/usr/lib/python3.5/asyncio/selector_events.py", line 451, in sock_connect
    return (yield from fut)
  File "/usr/lib/python3.5/asyncio/futures.py", line 380, in __iter__
    yield self  # This tells Task to wait for completion.
  File "/usr/lib/python3.5/asyncio/tasks.py", line 304, in _wakeup
    future.result()
  File "/usr/lib/python3.5/asyncio/futures.py", line 293, in result
    raise self._exception
  File "/usr/lib/python3.5/asyncio/selector_events.py", line 481, in _sock_connect_cb
    raise OSError(err, 'Connect call failed %s' % (address,))
OSError: [Errno 113] Connect call failed ('192.168.1.193', 8060)

The above exception was the direct cause of the following exception:

Traceback (most recent call last):
  File "/srv/homeassistant/lib/python3.5/site-packages/aiohttp/web_protocol.py", line 381, in start
    resp = await self._request_handler(request)
  File "/srv/homeassistant/lib/python3.5/site-packages/aiohttp/web_app.py", line 310, in _handle
    resp = await handler(request)
  File "/srv/homeassistant/lib/python3.5/site-packages/aiohttp/web_middlewares.py", line 88, in impl
    return await handler(request)
  File "/srv/homeassistant/lib/python3.5/site-packages/homeassistant/components/http/static.py", line 68, in staticresource_middleware
    return await handler(request)
  File "/srv/homeassistant/lib/python3.5/site-packages/homeassistant/components/http/real_ip.py", line 27, in real_ip_middleware
    return await handler(request)
  File "/srv/homeassistant/lib/python3.5/site-packages/homeassistant/components/http/ban.py", line 68, in ban_middleware
    return await handler(request)
  File "/srv/homeassistant/lib/python3.5/site-packages/homeassistant/components/http/auth.py", line 28, in auth_middleware
    return await handler(request)
  File "/srv/homeassistant/lib/python3.5/site-packages/homeassistant/components/http/view.py", line 100, in handle
    result = await result
  File "/srv/homeassistant/lib/python3.5/site-packages/homeassistant/components/media_player/__init__.py", line 944, in get
    data, content_type = yield from player.async_get_media_image()
  File "/srv/homeassistant/lib/python3.5/site-packages/homeassistant/components/media_player/__init__.py", line 499, in async_get_media_image
    return (yield from _async_fetch_image(self.hass, url))
  File "/srv/homeassistant/lib/python3.5/site-packages/homeassistant/components/media_player/__init__.py", line 901, in _async_fetch_image
    response = yield from websession.get(url)
  File "/srv/homeassistant/lib/python3.5/site-packages/aiohttp/client.py", line 319, in _request
    traces=traces
  File "/srv/homeassistant/lib/python3.5/site-packages/aiohttp/connector.py", line 418, in connect
    traces=traces
  File "/srv/homeassistant/lib/python3.5/site-packages/aiohttp/connector.py", line 736, in _create_connection
    traces=None
  File "/srv/homeassistant/lib/python3.5/site-packages/aiohttp/connector.py", line 855, in _create_direct_connection
    raise last_exc
  File "/srv/homeassistant/lib/python3.5/site-packages/aiohttp/connector.py", line 838, in _create_direct_connection
    req=req, client_error=client_error)
  File "/srv/homeassistant/lib/python3.5/site-packages/aiohttp/connector.py", line 807, in _wrap_create_connection
    raise client_error(req.connection_key, exc) from exc
aiohttp.client_exceptions.ClientConnectorError: Cannot connect to host 192.168.1.193:8060 ssl:False [Connect call failed ('192.168.1.193', 8060)]
2018-03-18 09:55:34 ERROR (MainThread) [aiohttp.server] Error handling request
Traceback (most recent call last):
  File "/srv/homeassistant/lib/python3.5/site-packages/aiohttp/connector.py", line 800, in _wrap_create_connection
    return await self._loop.create_connection(*args, **kwargs)
  File "/usr/lib/python3.5/asyncio/base_events.py", line 775, in create_connection
    raise exceptions[0]
  File "/usr/lib/python3.5/asyncio/base_events.py", line 762, in create_connection
    yield from self.sock_connect(sock, address)
  File "/usr/lib/python3.5/asyncio/selector_events.py", line 451, in sock_connect
    return (yield from fut)
  File "/usr/lib/python3.5/asyncio/futures.py", line 380, in __iter__
    yield self  # This tells Task to wait for completion.
  File "/usr/lib/python3.5/asyncio/tasks.py", line 304, in _wakeup
    future.result()
  File "/usr/lib/python3.5/asyncio/futures.py", line 293, in result
    raise self._exception
  File "/usr/lib/python3.5/asyncio/selector_events.py", line 481, in _sock_connect_cb
    raise OSError(err, 'Connect call failed %s' % (address,))
OSError: [Errno 113] Connect call failed ('192.168.1.193', 8060)

The above exception was the direct cause of the following exception:

Traceback (most recent call last):
  File "/srv/homeassistant/lib/python3.5/site-packages/aiohttp/web_protocol.py", line 381, in start
    resp = await self._request_handler(request)
  File "/srv/homeassistant/lib/python3.5/site-packages/aiohttp/web_app.py", line 310, in _handle
    resp = await handler(request)
  File "/srv/homeassistant/lib/python3.5/site-packages/aiohttp/web_middlewares.py", line 88, in impl
    return await handler(request)
  File "/srv/homeassistant/lib/python3.5/site-packages/homeassistant/components/http/static.py", line 68, in staticresource_middleware
    return await handler(request)
  File "/srv/homeassistant/lib/python3.5/site-packages/homeassistant/components/http/real_ip.py", line 27, in real_ip_middleware
    return await handler(request)
  File "/srv/homeassistant/lib/python3.5/site-packages/homeassistant/components/http/ban.py", line 68, in ban_middleware
    return await handler(request)
  File "/srv/homeassistant/lib/python3.5/site-packages/homeassistant/components/http/auth.py", line 28, in auth_middleware
    return await handler(request)
  File "/srv/homeassistant/lib/python3.5/site-packages/homeassistant/components/http/view.py", line 100, in handle
    result = await result
  File "/srv/homeassistant/lib/python3.5/site-packages/homeassistant/components/media_player/__init__.py", line 944, in get
    data, content_type = yield from player.async_get_media_image()
  File "/srv/homeassistant/lib/python3.5/site-packages/homeassistant/components/media_player/__init__.py", line 499, in async_get_media_image
    return (yield from _async_fetch_image(self.hass, url))
  File "/srv/homeassistant/lib/python3.5/site-packages/homeassistant/components/media_player/__init__.py", line 901, in _async_fetch_image
    response = yield from websession.get(url)
  File "/srv/homeassistant/lib/python3.5/site-packages/aiohttp/client.py", line 319, in _request
    traces=traces
  File "/srv/homeassistant/lib/python3.5/site-packages/aiohttp/connector.py", line 418, in connect
    traces=traces
  File "/srv/homeassistant/lib/python3.5/site-packages/aiohttp/connector.py", line 736, in _create_connection
    traces=None
  File "/srv/homeassistant/lib/python3.5/site-packages/aiohttp/connector.py", line 855, in _create_direct_connection
    raise last_exc
  File "/srv/homeassistant/lib/python3.5/site-packages/aiohttp/connector.py", line 838, in _create_direct_connection
    req=req, client_error=client_error)
  File "/srv/homeassistant/lib/python3.5/site-packages/aiohttp/connector.py", line 807, in _wrap_create_connection
    raise client_error(req.connection_key, exc) from exc
aiohttp.client_exceptions.ClientConnectorError: Cannot connect to host 192.168.1.193:8060 ssl:False [Connect call failed ('192.168.1.193', 8060)]
2018-03-18 09:56:32 ERROR (MainThread) [aiohttp.server] Error handling request
Traceback (most recent call last):
  File "/srv/homeassistant/lib/python3.5/site-packages/aiohttp/connector.py", line 800, in _wrap_create_connection
    return await self._loop.create_connection(*args, **kwargs)
  File "/usr/lib/python3.5/asyncio/base_events.py", line 775, in create_connection
    raise exceptions[0]
  File "/usr/lib/python3.5/asyncio/base_events.py", line 762, in create_connection
    yield from self.sock_connect(sock, address)
  File "/usr/lib/python3.5/asyncio/selector_events.py", line 451, in sock_connect
    return (yield from fut)
  File "/usr/lib/python3.5/asyncio/futures.py", line 380, in __iter__
    yield self  # This tells Task to wait for completion.
  File "/usr/lib/python3.5/asyncio/tasks.py", line 304, in _wakeup
    future.result()
  File "/usr/lib/python3.5/asyncio/futures.py", line 293, in result
    raise self._exception
  File "/usr/lib/python3.5/asyncio/selector_events.py", line 481, in _sock_connect_cb
    raise OSError(err, 'Connect call failed %s' % (address,))
OSError: [Errno 113] Connect call failed ('192.168.1.193', 8060)

The above exception was the direct cause of the following exception:

Traceback (most recent call last):
  File "/srv/homeassistant/lib/python3.5/site-packages/aiohttp/web_protocol.py", line 381, in start
    resp = await self._request_handler(request)
  File "/srv/homeassistant/lib/python3.5/site-packages/aiohttp/web_app.py", line 310, in _handle
    resp = await handler(request)
  File "/srv/homeassistant/lib/python3.5/site-packages/aiohttp/web_middlewares.py", line 88, in impl
    return await handler(request)
  File "/srv/homeassistant/lib/python3.5/site-packages/homeassistant/components/http/static.py", line 68, in staticresource_middleware
    return await handler(request)
  File "/srv/homeassistant/lib/python3.5/site-packages/homeassistant/components/http/real_ip.py", line 27, in real_ip_middleware
    return await handler(request)
  File "/srv/homeassistant/lib/python3.5/site-packages/homeassistant/components/http/ban.py", line 68, in ban_middleware
    return await handler(request)
  File "/srv/homeassistant/lib/python3.5/site-packages/homeassistant/components/http/auth.py", line 28, in auth_middleware
    return await handler(request)
  File "/srv/homeassistant/lib/python3.5/site-packages/homeassistant/components/http/view.py", line 100, in handle
    result = await result
  File "/srv/homeassistant/lib/python3.5/site-packages/homeassistant/components/media_player/__init__.py", line 944, in get
    data, content_type = yield from player.async_get_media_image()
  File "/srv/homeassistant/lib/python3.5/site-packages/homeassistant/components/media_player/__init__.py", line 499, in async_get_media_image
    return (yield from _async_fetch_image(self.hass, url))
  File "/srv/homeassistant/lib/python3.5/site-packages/homeassistant/components/media_player/__init__.py", line 901, in _async_fetch_image
    response = yield from websession.get(url)
  File "/srv/homeassistant/lib/python3.5/site-packages/aiohttp/client.py", line 319, in _request
    traces=traces
  File "/srv/homeassistant/lib/python3.5/site-packages/aiohttp/connector.py", line 418, in connect
    traces=traces
  File "/srv/homeassistant/lib/python3.5/site-packages/aiohttp/connector.py", line 736, in _create_connection
    traces=None
  File "/srv/homeassistant/lib/python3.5/site-packages/aiohttp/connector.py", line 855, in _create_direct_connection
    raise last_exc
  File "/srv/homeassistant/lib/python3.5/site-packages/aiohttp/connector.py", line 838, in _create_direct_connection
    req=req, client_error=client_error)
  File "/srv/homeassistant/lib/python3.5/site-packages/aiohttp/connector.py", line 807, in _wrap_create_connection
    raise client_error(req.connection_key, exc) from exc
aiohttp.client_exceptions.ClientConnectorError: Cannot connect to host 192.168.1.193:8060 ssl:False [Connect call failed ('192.168.1.193', 8060)]
2018-03-18 09:57:34 ERROR (MainThread) [aiohttp.server] Error handling request
Traceback (most recent call last):
  File "/srv/homeassistant/lib/python3.5/site-packages/aiohttp/connector.py", line 800, in _wrap_create_connection
    return await self._loop.create_connection(*args, **kwargs)
  File "/usr/lib/python3.5/asyncio/base_events.py", line 775, in create_connection
    raise exceptions[0]
  File "/usr/lib/python3.5/asyncio/base_events.py", line 762, in create_connection
    yield from self.sock_connect(sock, address)
  File "/usr/lib/python3.5/asyncio/selector_events.py", line 451, in sock_connect
    return (yield from fut)
  File "/usr/lib/python3.5/asyncio/futures.py", line 380, in __iter__
    yield self  # This tells Task to wait for completion.
  File "/usr/lib/python3.5/asyncio/tasks.py", line 304, in _wakeup
    future.result()
  File "/usr/lib/python3.5/asyncio/futures.py", line 293, in result
    raise self._exception
  File "/usr/lib/python3.5/asyncio/selector_events.py", line 481, in _sock_connect_cb
    raise OSError(err, 'Connect call failed %s' % (address,))
OSError: [Errno 113] Connect call failed ('192.168.1.193', 8060)

The above exception was the direct cause of the following exception:

Traceback (most recent call last):
  File "/srv/homeassistant/lib/python3.5/site-packages/aiohttp/web_protocol.py", line 381, in start
    resp = await self._request_handler(request)
  File "/srv/homeassistant/lib/python3.5/site-packages/aiohttp/web_app.py", line 310, in _handle
    resp = await handler(request)
  File "/srv/homeassistant/lib/python3.5/site-packages/aiohttp/web_middlewares.py", line 88, in impl
    return await handler(request)
  File "/srv/homeassistant/lib/python3.5/site-packages/homeassistant/components/http/static.py", line 68, in staticresource_middleware
    return await handler(request)
  File "/srv/homeassistant/lib/python3.5/site-packages/homeassistant/components/http/real_ip.py", line 27, in real_ip_middleware
    return await handler(request)
  File "/srv/homeassistant/lib/python3.5/site-packages/homeassistant/components/http/ban.py", line 68, in ban_middleware
    return await handler(request)
  File "/srv/homeassistant/lib/python3.5/site-packages/homeassistant/components/http/auth.py", line 28, in auth_middleware
    return await handler(request)
  File "/srv/homeassistant/lib/python3.5/site-packages/homeassistant/components/http/view.py", line 100, in handle
    result = await result
  File "/srv/homeassistant/lib/python3.5/site-packages/homeassistant/components/media_player/__init__.py", line 944, in get
    data, content_type = yield from player.async_get_media_image()
  File "/srv/homeassistant/lib/python3.5/site-packages/homeassistant/components/media_player/__init__.py", line 499, in async_get_media_image
    return (yield from _async_fetch_image(self.hass, url))
  File "/srv/homeassistant/lib/python3.5/site-packages/homeassistant/components/media_player/__init__.py", line 901, in _async_fetch_image
    response = yield from websession.get(url)
  File "/srv/homeassistant/lib/python3.5/site-packages/aiohttp/client.py", line 319, in _request
    traces=traces
  File "/srv/homeassistant/lib/python3.5/site-packages/aiohttp/connector.py", line 418, in connect
    traces=traces
  File "/srv/homeassistant/lib/python3.5/site-packages/aiohttp/connector.py", line 736, in _create_connection
    traces=None
  File "/srv/homeassistant/lib/python3.5/site-packages/aiohttp/connector.py", line 855, in _create_direct_connection
    raise last_exc
  File "/srv/homeassistant/lib/python3.5/site-packages/aiohttp/connector.py", line 838, in _create_direct_connection
    req=req, client_error=client_error)
  File "/srv/homeassistant/lib/python3.5/site-packages/aiohttp/connector.py", line 807, in _wrap_create_connection
    raise client_error(req.connection_key, exc) from exc
aiohttp.client_exceptions.ClientConnectorError: Cannot connect to host 192.168.1.193:8060 ssl:False [Connect call failed ('192.168.1.193', 8060)]
2018-03-18 09:58:33 ERROR (MainThread) [aiohttp.server] Error handling request
Traceback (most recent call last):
  File "/srv/homeassistant/lib/python3.5/site-packages/aiohttp/connector.py", line 800, in _wrap_create_connection
    return await self._loop.create_connection(*args, **kwargs)
  File "/usr/lib/python3.5/asyncio/base_events.py", line 775, in create_connection
    raise exceptions[0]
  File "/usr/lib/python3.5/asyncio/base_events.py", line 762, in create_connection
    yield from self.sock_connect(sock, address)
  File "/usr/lib/python3.5/asyncio/selector_events.py", line 451, in sock_connect
    return (yield from fut)
  File "/usr/lib/python3.5/asyncio/futures.py", line 380, in __iter__
    yield self  # This tells Task to wait for completion.
  File "/usr/lib/python3.5/asyncio/tasks.py", line 304, in _wakeup
    future.result()
  File "/usr/lib/python3.5/asyncio/futures.py", line 293, in result
    raise self._exception
  File "/usr/lib/python3.5/asyncio/selector_events.py", line 481, in _sock_connect_cb
    raise OSError(err, 'Connect call failed %s' % (address,))
OSError: [Errno 113] Connect call failed ('192.168.1.193', 8060)

The above exception was the direct cause of the following exception:

Traceback (most recent call last):
  File "/srv/homeassistant/lib/python3.5/site-packages/aiohttp/web_protocol.py", line 381, in start
    resp = await self._request_handler(request)
  File "/srv/homeassistant/lib/python3.5/site-packages/aiohttp/web_app.py", line 310, in _handle
    resp = await handler(request)
  File "/srv/homeassistant/lib/python3.5/site-packages/aiohttp/web_middlewares.py", line 88, in impl
    return await handler(request)
  File "/srv/homeassistant/lib/python3.5/site-packages/homeassistant/components/http/static.py", line 68, in staticresource_middleware
    return await handler(request)
  File "/srv/homeassistant/lib/python3.5/site-packages/homeassistant/components/http/real_ip.py", line 27, in real_ip_middleware
    return await handler(request)
  File "/srv/homeassistant/lib/python3.5/site-packages/homeassistant/components/http/ban.py", line 68, in ban_middleware
    return await handler(request)
  File "/srv/homeassistant/lib/python3.5/site-packages/homeassistant/components/http/auth.py", line 28, in auth_middleware
    return await handler(request)
  File "/srv/homeassistant/lib/python3.5/site-packages/homeassistant/components/http/view.py", line 100, in handle
    result = await result
  File "/srv/homeassistant/lib/python3.5/site-packages/homeassistant/components/media_player/__init__.py", line 944, in get
    data, content_type = yield from player.async_get_media_image()
  File "/srv/homeassistant/lib/python3.5/site-packages/homeassistant/components/media_player/__init__.py", line 499, in async_get_media_image
    return (yield from _async_fetch_image(self.hass, url))
  File "/srv/homeassistant/lib/python3.5/site-packages/homeassistant/components/media_player/__init__.py", line 901, in _async_fetch_image
    response = yield from websession.get(url)
  File "/srv/homeassistant/lib/python3.5/site-packages/aiohttp/client.py", line 319, in _request
    traces=traces
  File "/srv/homeassistant/lib/python3.5/site-packages/aiohttp/connector.py", line 418, in connect
    traces=traces
  File "/srv/homeassistant/lib/python3.5/site-packages/aiohttp/connector.py", line 736, in _create_connection
    traces=None
  File "/srv/homeassistant/lib/python3.5/site-packages/aiohttp/connector.py", line 855, in _create_direct_connection
    raise last_exc
  File "/srv/homeassistant/lib/python3.5/site-packages/aiohttp/connector.py", line 838, in _create_direct_connection
    req=req, client_error=client_error)
  File "/srv/homeassistant/lib/python3.5/site-packages/aiohttp/connector.py", line 807, in _wrap_create_connection
    raise client_error(req.connection_key, exc) from exc
aiohttp.client_exceptions.ClientConnectorError: Cannot connect to host 192.168.1.193:8060 ssl:False [Connect call failed ('192.168.1.193', 8060)]
2018-03-18 09:59:31 ERROR (MainThread) [aiohttp.server] Error handling request
Traceback (most recent call last):
  File "/srv/homeassistant/lib/python3.5/site-packages/aiohttp/connector.py", line 800, in _wrap_create_connection
    return await self._loop.create_connection(*args, **kwargs)
  File "/usr/lib/python3.5/asyncio/base_events.py", line 775, in create_connection
    raise exceptions[0]
  File "/usr/lib/python3.5/asyncio/base_events.py", line 762, in create_connection
    yield from self.sock_connect(sock, address)
  File "/usr/lib/python3.5/asyncio/selector_events.py", line 451, in sock_connect
    return (yield from fut)
  File "/usr/lib/python3.5/asyncio/futures.py", line 380, in __iter__
    yield self  # This tells Task to wait for completion.
  File "/usr/lib/python3.5/asyncio/tasks.py", line 304, in _wakeup
    future.result()
  File "/usr/lib/python3.5/asyncio/futures.py", line 293, in result
    raise self._exception
  File "/usr/lib/python3.5/asyncio/selector_events.py", line 481, in _sock_connect_cb
    raise OSError(err, 'Connect call failed %s' % (address,))
OSError: [Errno 113] Connect call failed ('192.168.1.193', 8060)

The above exception was the direct cause of the following exception:

Traceback (most recent call last):
  File "/srv/homeassistant/lib/python3.5/site-packages/aiohttp/web_protocol.py", line 381, in start
    resp = await self._request_handler(request)
  File "/srv/homeassistant/lib/python3.5/site-packages/aiohttp/web_app.py", line 310, in _handle
    resp = await handler(request)
  File "/srv/homeassistant/lib/python3.5/site-packages/aiohttp/web_middlewares.py", line 88, in impl
    return await handler(request)
  File "/srv/homeassistant/lib/python3.5/site-packages/homeassistant/components/http/static.py", line 68, in staticresource_middleware
    return await handler(request)
  File "/srv/homeassistant/lib/python3.5/site-packages/homeassistant/components/http/real_ip.py", line 27, in real_ip_middleware
    return await handler(request)
  File "/srv/homeassistant/lib/python3.5/site-packages/homeassistant/components/http/ban.py", line 68, in ban_middleware
    return await handler(request)
  File "/srv/homeassistant/lib/python3.5/site-packages/homeassistant/components/http/auth.py", line 28, in auth_middleware
    return await handler(request)
  File "/srv/homeassistant/lib/python3.5/site-packages/homeassistant/components/http/view.py", line 100, in handle
    result = await result
  File "/srv/homeassistant/lib/python3.5/site-packages/homeassistant/components/media_player/__init__.py", line 944, in get
    data, content_type = yield from player.async_get_media_image()
  File "/srv/homeassistant/lib/python3.5/site-packages/homeassistant/components/media_player/__init__.py", line 499, in async_get_media_image
    return (yield from _async_fetch_image(self.hass, url))
  File "/srv/homeassistant/lib/python3.5/site-packages/homeassistant/components/media_player/__init__.py", line 901, in _async_fetch_image
    response = yield from websession.get(url)
  File "/srv/homeassistant/lib/python3.5/site-packages/aiohttp/client.py", line 319, in _request
    traces=traces
  File "/srv/homeassistant/lib/python3.5/site-packages/aiohttp/connector.py", line 418, in connect
    traces=traces
  File "/srv/homeassistant/lib/python3.5/site-packages/aiohttp/connector.py", line 736, in _create_connection
    traces=None
  File "/srv/homeassistant/lib/python3.5/site-packages/aiohttp/connector.py", line 855, in _create_direct_connection
    raise last_exc
  File "/srv/homeassistant/lib/python3.5/site-packages/aiohttp/connector.py", line 838, in _create_direct_connection
    req=req, client_error=client_error)
  File "/srv/homeassistant/lib/python3.5/site-packages/aiohttp/connector.py", line 807, in _wrap_create_connection
    raise client_error(req.connection_key, exc) from exc
aiohttp.client_exceptions.ClientConnectorError: Cannot connect to host 192.168.1.193:8060 ssl:False [Connect call failed ('192.168.1.193', 8060)]
2018-03-18 10:00:34 ERROR (MainThread) [aiohttp.server] Error handling request
Traceback (most recent call last):
  File "/srv/homeassistant/lib/python3.5/site-packages/aiohttp/connector.py", line 800, in _wrap_create_connection
    return await self._loop.create_connection(*args, **kwargs)
  File "/usr/lib/python3.5/asyncio/base_events.py", line 775, in create_connection
    raise exceptions[0]
  File "/usr/lib/python3.5/asyncio/base_events.py", line 762, in create_connection
    yield from self.sock_connect(sock, address)
  File "/usr/lib/python3.5/asyncio/selector_events.py", line 451, in sock_connect
    return (yield from fut)
  File "/usr/lib/python3.5/asyncio/futures.py", line 380, in __iter__
    yield self  # This tells Task to wait for completion.
  File "/usr/lib/python3.5/asyncio/tasks.py", line 304, in _wakeup
    future.result()
  File "/usr/lib/python3.5/asyncio/futures.py", line 293, in result
    raise self._exception
  File "/usr/lib/python3.5/asyncio/selector_events.py", line 481, in _sock_connect_cb
    raise OSError(err, 'Connect call failed %s' % (address,))
OSError: [Errno 113] Connect call failed ('192.168.1.193', 8060)

The above exception was the direct cause of the following exception:

Traceback (most recent call last):
  File "/srv/homeassistant/lib/python3.5/site-packages/aiohttp/web_protocol.py", line 381, in start
    resp = await self._request_handler(request)
  File "/srv/homeassistant/lib/python3.5/site-packages/aiohttp/web_app.py", line 310, in _handle
    resp = await handler(request)
  File "/srv/homeassistant/lib/python3.5/site-packages/aiohttp/web_middlewares.py", line 88, in impl
    return await handler(request)
  File "/srv/homeassistant/lib/python3.5/site-packages/homeassistant/components/http/static.py", line 68, in staticresource_middleware
    return await handler(request)
  File "/srv/homeassistant/lib/python3.5/site-packages/homeassistant/components/http/real_ip.py", line 27, in real_ip_middleware
    return await handler(request)
  File "/srv/homeassistant/lib/python3.5/site-packages/homeassistant/components/http/ban.py", line 68, in ban_middleware
    return await handler(request)
  File "/srv/homeassistant/lib/python3.5/site-packages/homeassistant/components/http/auth.py", line 28, in auth_middleware
    return await handler(request)
  File "/srv/homeassistant/lib/python3.5/site-packages/homeassistant/components/http/view.py", line 100, in handle
    result = await result
  File "/srv/homeassistant/lib/python3.5/site-packages/homeassistant/components/media_player/__init__.py", line 944, in get
    data, content_type = yield from player.async_get_media_image()
  File "/srv/homeassistant/lib/python3.5/site-packages/homeassistant/components/media_player/__init__.py", line 499, in async_get_media_image
    return (yield from _async_fetch_image(self.hass, url))
  File "/srv/homeassistant/lib/python3.5/site-packages/homeassistant/components/media_player/__init__.py", line 901, in _async_fetch_image
    response = yield from websession.get(url)
  File "/srv/homeassistant/lib/python3.5/site-packages/aiohttp/client.py", line 319, in _request
    traces=traces
  File "/srv/homeassistant/lib/python3.5/site-packages/aiohttp/connector.py", line 418, in connect
    traces=traces
  File "/srv/homeassistant/lib/python3.5/site-packages/aiohttp/connector.py", line 736, in _create_connection
    traces=None
  File "/srv/homeassistant/lib/python3.5/site-packages/aiohttp/connector.py", line 855, in _create_direct_connection
    raise last_exc
  File "/srv/homeassistant/lib/python3.5/site-packages/aiohttp/connector.py", line 838, in _create_direct_connection
    req=req, client_error=client_error)
  File "/srv/homeassistant/lib/python3.5/site-packages/aiohttp/connector.py", line 807, in _wrap_create_connection
    raise client_error(req.connection_key, exc) from exc
aiohttp.client_exceptions.ClientConnectorError: Cannot connect to host 192.168.1.193:8060 ssl:False [Connect call failed ('192.168.1.193', 8060)]
2018-03-18 10:01:32 ERROR (MainThread) [aiohttp.server] Error handling request
Traceback (most recent call last):
  File "/srv/homeassistant/lib/python3.5/site-packages/aiohttp/connector.py", line 800, in _wrap_create_connection
    return await self._loop.create_connection(*args, **kwargs)
  File "/usr/lib/python3.5/asyncio/base_events.py", line 775, in create_connection
    raise exceptions[0]
  File "/usr/lib/python3.5/asyncio/base_events.py", line 762, in create_connection
    yield from self.sock_connect(sock, address)
  File "/usr/lib/python3.5/asyncio/selector_events.py", line 451, in sock_connect
    return (yield from fut)
  File "/usr/lib/python3.5/asyncio/futures.py", line 380, in __iter__
    yield self  # This tells Task to wait for completion.
  File "/usr/lib/python3.5/asyncio/tasks.py", line 304, in _wakeup
    future.result()
  File "/usr/lib/python3.5/asyncio/futures.py", line 293, in result
    raise self._exception
  File "/usr/lib/python3.5/asyncio/selector_events.py", line 481, in _sock_connect_cb
    raise OSError(err, 'Connect call failed %s' % (address,))
OSError: [Errno 113] Connect call failed ('192.168.1.193', 8060)

The above exception was the direct cause of the following exception:

Traceback (most recent call last):
  File "/srv/homeassistant/lib/python3.5/site-packages/aiohttp/web_protocol.py", line 381, in start
    resp = await self._request_handler(request)
  File "/srv/homeassistant/lib/python3.5/site-packages/aiohttp/web_app.py", line 310, in _handle
    resp = await handler(request)
  File "/srv/homeassistant/lib/python3.5/site-packages/aiohttp/web_middlewares.py", line 88, in impl
    return await handler(request)
  File "/srv/homeassistant/lib/python3.5/site-packages/homeassistant/components/http/static.py", line 68, in staticresource_middleware
    return await handler(request)
  File "/srv/homeassistant/lib/python3.5/site-packages/homeassistant/components/http/real_ip.py", line 27, in real_ip_middleware
    return await handler(request)
  File "/srv/homeassistant/lib/python3.5/site-packages/homeassistant/components/http/ban.py", line 68, in ban_middleware
    return await handler(request)
  File "/srv/homeassistant/lib/python3.5/site-packages/homeassistant/components/http/auth.py", line 28, in auth_middleware
    return await handler(request)
  File "/srv/homeassistant/lib/python3.5/site-packages/homeassistant/components/http/view.py", line 100, in handle
    result = await result
  File "/srv/homeassistant/lib/python3.5/site-packages/homeassistant/components/media_player/__init__.py", line 944, in get
    data, content_type = yield from player.async_get_media_image()
  File "/srv/homeassistant/lib/python3.5/site-packages/homeassistant/components/media_player/__init__.py", line 499, in async_get_media_image
    return (yield from _async_fetch_image(self.hass, url))
  File "/srv/homeassistant/lib/python3.5/site-packages/homeassistant/components/media_player/__init__.py", line 901, in _async_fetch_image
    response = yield from websession.get(url)
  File "/srv/homeassistant/lib/python3.5/site-packages/aiohttp/client.py", line 319, in _request
    traces=traces
  File "/srv/homeassistant/lib/python3.5/site-packages/aiohttp/connector.py", line 418, in connect
    traces=traces
  File "/srv/homeassistant/lib/python3.5/site-packages/aiohttp/connector.py", line 736, in _create_connection
    traces=None
  File "/srv/homeassistant/lib/python3.5/site-packages/aiohttp/connector.py", line 855, in _create_direct_connection
    raise last_exc
  File "/srv/homeassistant/lib/python3.5/site-packages/aiohttp/connector.py", line 838, in _create_direct_connection
    req=req, client_error=client_error)
  File "/srv/homeassistant/lib/python3.5/site-packages/aiohttp/connector.py", line 807, in _wrap_create_connection
    raise client_error(req.connection_key, exc) from exc
aiohttp.client_exceptions.ClientConnectorError: Cannot connect to host 192.168.1.193:8060 ssl:False [Connect call failed ('192.168.1.193', 8060)]
2018-03-18 10:02:34 ERROR (MainThread) [aiohttp.server] Error handling request
Traceback (most recent call last):
  File "/srv/homeassistant/lib/python3.5/site-packages/aiohttp/connector.py", line 800, in _wrap_create_connection
    return await self._loop.create_connection(*args, **kwargs)
  File "/usr/lib/python3.5/asyncio/base_events.py", line 775, in create_connection
    raise exceptions[0]
  File "/usr/lib/python3.5/asyncio/base_events.py", line 762, in create_connection
    yield from self.sock_connect(sock, address)
  File "/usr/lib/python3.5/asyncio/selector_events.py", line 451, in sock_connect
    return (yield from fut)
  File "/usr/lib/python3.5/asyncio/futures.py", line 380, in __iter__
    yield self  # This tells Task to wait for completion.
  File "/usr/lib/python3.5/asyncio/tasks.py", line 304, in _wakeup
    future.result()
  File "/usr/lib/python3.5/asyncio/futures.py", line 293, in result
    raise self._exception
  File "/usr/lib/python3.5/asyncio/selector_events.py", line 481, in _sock_connect_cb
    raise OSError(err, 'Connect call failed %s' % (address,))
OSError: [Errno 113] Connect call failed ('192.168.1.193', 8060)

The above exception was the direct cause of the following exception:

Traceback (most recent call last):
  File "/srv/homeassistant/lib/python3.5/site-packages/aiohttp/web_protocol.py", line 381, in start
    resp = await self._request_handler(request)
  File "/srv/homeassistant/lib/python3.5/site-packages/aiohttp/web_app.py", line 310, in _handle
    resp = await handler(request)
  File "/srv/homeassistant/lib/python3.5/site-packages/aiohttp/web_middlewares.py", line 88, in impl
    return await handler(request)
  File "/srv/homeassistant/lib/python3.5/site-packages/homeassistant/components/http/static.py", line 68, in staticresource_middleware
    return await handler(request)
  File "/srv/homeassistant/lib/python3.5/site-packages/homeassistant/components/http/real_ip.py", line 27, in real_ip_middleware
    return await handler(request)
  File "/srv/homeassistant/lib/python3.5/site-packages/homeassistant/components/http/ban.py", line 68, in ban_middleware
    return await handler(request)
  File "/srv/homeassistant/lib/python3.5/site-packages/homeassistant/components/http/auth.py", line 28, in auth_middleware
    return await handler(request)
  File "/srv/homeassistant/lib/python3.5/site-packages/homeassistant/components/http/view.py", line 100, in handle
    result = await result
  File "/srv/homeassistant/lib/python3.5/site-packages/homeassistant/components/media_player/__init__.py", line 944, in get
    data, content_type = yield from player.async_get_media_image()
  File "/srv/homeassistant/lib/python3.5/site-packages/homeassistant/components/media_player/__init__.py", line 499, in async_get_media_image
    return (yield from _async_fetch_image(self.hass, url))
  File "/srv/homeassistant/lib/python3.5/site-packages/homeassistant/components/media_player/__init__.py", line 901, in _async_fetch_image
    response = yield from websession.get(url)
  File "/srv/homeassistant/lib/python3.5/site-packages/aiohttp/client.py", line 319, in _request
    traces=traces
  File "/srv/homeassistant/lib/python3.5/site-packages/aiohttp/connector.py", line 418, in connect
    traces=traces
  File "/srv/homeassistant/lib/python3.5/site-packages/aiohttp/connector.py", line 736, in _create_connection
    traces=None
  File "/srv/homeassistant/lib/python3.5/site-packages/aiohttp/connector.py", line 855, in _create_direct_connection
    raise last_exc
  File "/srv/homeassistant/lib/python3.5/site-packages/aiohttp/connector.py", line 838, in _create_direct_connection
    req=req, client_error=client_error)
  File "/srv/homeassistant/lib/python3.5/site-packages/aiohttp/connector.py", line 807, in _wrap_create_connection
    raise client_error(req.connection_key, exc) from exc
aiohttp.client_exceptions.ClientConnectorError: Cannot connect to host 192.168.1.193:8060 ssl:False [Connect call failed ('192.168.1.193', 8060)]
2018-03-18 10:03:33 ERROR (MainThread) [aiohttp.server] Error handling request
Traceback (most recent call last):
  File "/srv/homeassistant/lib/python3.5/site-packages/aiohttp/connector.py", line 800, in _wrap_create_connection
    return await self._loop.create_connection(*args, **kwargs)
  File "/usr/lib/python3.5/asyncio/base_events.py", line 775, in create_connection
    raise exceptions[0]
  File "/usr/lib/python3.5/asyncio/base_events.py", line 762, in create_connection
    yield from self.sock_connect(sock, address)
  File "/usr/lib/python3.5/asyncio/selector_events.py", line 451, in sock_connect
    return (yield from fut)
  File "/usr/lib/python3.5/asyncio/futures.py", line 380, in __iter__
    yield self  # This tells Task to wait for completion.
  File "/usr/lib/python3.5/asyncio/tasks.py", line 304, in _wakeup
    future.result()
  File "/usr/lib/python3.5/asyncio/futures.py", line 293, in result
    raise self._exception
  File "/usr/lib/python3.5/asyncio/selector_events.py", line 481, in _sock_connect_cb
    raise OSError(err, 'Connect call failed %s' % (address,))
OSError: [Errno 113] Connect call failed ('192.168.1.193', 8060)

The above exception was the direct cause of the following exception:

Traceback (most recent call last):
  File "/srv/homeassistant/lib/python3.5/site-packages/aiohttp/web_protocol.py", line 381, in start
    resp = await self._request_handler(request)
  File "/srv/homeassistant/lib/python3.5/site-packages/aiohttp/web_app.py", line 310, in _handle
    resp = await handler(request)
  File "/srv/homeassistant/lib/python3.5/site-packages/aiohttp/web_middlewares.py", line 88, in impl
    return await handler(request)
  File "/srv/homeassistant/lib/python3.5/site-packages/homeassistant/components/http/static.py", line 68, in staticresource_middleware
    return await handler(request)
  File "/srv/homeassistant/lib/python3.5/site-packages/homeassistant/components/http/real_ip.py", line 27, in real_ip_middleware
    return await handler(request)
  File "/srv/homeassistant/lib/python3.5/site-packages/homeassistant/components/http/ban.py", line 68, in ban_middleware
    return await handler(request)
  File "/srv/homeassistant/lib/python3.5/site-packages/homeassistant/components/http/auth.py", line 28, in auth_middleware
    return await handler(request)
  File "/srv/homeassistant/lib/python3.5/site-packages/homeassistant/components/http/view.py", line 100, in handle
    result = await result
  File "/srv/homeassistant/lib/python3.5/site-packages/homeassistant/components/media_player/__init__.py", line 944, in get
    data, content_type = yield from player.async_get_media_image()
  File "/srv/homeassistant/lib/python3.5/site-packages/homeassistant/components/media_player/__init__.py", line 499, in async_get_media_image
    return (yield from _async_fetch_image(self.hass, url))
  File "/srv/homeassistant/lib/python3.5/site-packages/homeassistant/components/media_player/__init__.py", line 901, in _async_fetch_image
    response = yield from websession.get(url)
  File "/srv/homeassistant/lib/python3.5/site-packages/aiohttp/client.py", line 319, in _request
    traces=traces
  File "/srv/homeassistant/lib/python3.5/site-packages/aiohttp/connector.py", line 418, in connect
    traces=traces
  File "/srv/homeassistant/lib/python3.5/site-packages/aiohttp/connector.py", line 736, in _create_connection
    traces=None
  File "/srv/homeassistant/lib/python3.5/site-packages/aiohttp/connector.py", line 855, in _create_direct_connection
    raise last_exc
  File "/srv/homeassistant/lib/python3.5/site-packages/aiohttp/connector.py", line 838, in _create_direct_connection
    req=req, client_error=client_error)
  File "/srv/homeassistant/lib/python3.5/site-packages/aiohttp/connector.py", line 807, in _wrap_create_connection
    raise client_error(req.connection_key, exc) from exc
aiohttp.client_exceptions.ClientConnectorError: Cannot connect to host 192.168.1.193:8060 ssl:False [Connect call failed ('192.168.1.193', 8060)]
2018-03-18 10:04:34 ERROR (MainThread) [aiohttp.server] Error handling request
Traceback (most recent call last):
  File "/srv/homeassistant/lib/python3.5/site-packages/aiohttp/connector.py", line 800, in _wrap_create_connection
    return await self._loop.create_connection(*args, **kwargs)
  File "/usr/lib/python3.5/asyncio/base_events.py", line 775, in create_connection
    raise exceptions[0]
  File "/usr/lib/python3.5/asyncio/base_events.py", line 762, in create_connection
    yield from self.sock_connect(sock, address)
  File "/usr/lib/python3.5/asyncio/selector_events.py", line 451, in sock_connect
    return (yield from fut)
  File "/usr/lib/python3.5/asyncio/futures.py", line 380, in __iter__
    yield self  # This tells Task to wait for completion.
  File "/usr/lib/python3.5/asyncio/tasks.py", line 304, in _wakeup
    future.result()
  File "/usr/lib/python3.5/asyncio/futures.py", line 293, in result
    raise self._exception
  File "/usr/lib/python3.5/asyncio/selector_events.py", line 481, in _sock_connect_cb
    raise OSError(err, 'Connect call failed %s' % (address,))
OSError: [Errno 113] Connect call failed ('192.168.1.193', 8060)

The above exception was the direct cause of the following exception:

Traceback (most recent call last):
  File "/srv/homeassistant/lib/python3.5/site-packages/aiohttp/web_protocol.py", line 381, in start
    resp = await self._request_handler(request)
  File "/srv/homeassistant/lib/python3.5/site-packages/aiohttp/web_app.py", line 310, in _handle
    resp = await handler(request)
  File "/srv/homeassistant/lib/python3.5/site-packages/aiohttp/web_middlewares.py", line 88, in impl
    return await handler(request)
  File "/srv/homeassistant/lib/python3.5/site-packages/homeassistant/components/http/static.py", line 68, in staticresource_middleware
    return await handler(request)
  File "/srv/homeassistant/lib/python3.5/site-packages/homeassistant/components/http/real_ip.py", line 27, in real_ip_middleware
    return await handler(request)
  File "/srv/homeassistant/lib/python3.5/site-packages/homeassistant/components/http/ban.py", line 68, in ban_middleware
    return await handler(request)
  File "/srv/homeassistant/lib/python3.5/site-packages/homeassistant/components/http/auth.py", line 28, in auth_middleware
    return await handler(request)
  File "/srv/homeassistant/lib/python3.5/site-packages/homeassistant/components/http/view.py", line 100, in handle
    result = await result
  File "/srv/homeassistant/lib/python3.5/site-packages/homeassistant/components/media_player/__init__.py", line 944, in get
    data, content_type = yield from player.async_get_media_image()
  File "/srv/homeassistant/lib/python3.5/site-packages/homeassistant/components/media_player/__init__.py", line 499, in async_get_media_image
    return (yield from _async_fetch_image(self.hass, url))
  File "/srv/homeassistant/lib/python3.5/site-packages/homeassistant/components/media_player/__init__.py", line 901, in _async_fetch_image
    response = yield from websession.get(url)
  File "/srv/homeassistant/lib/python3.5/site-packages/aiohttp/client.py", line 319, in _request
    traces=traces
  File "/srv/homeassistant/lib/python3.5/site-packages/aiohttp/connector.py", line 418, in connect
    traces=traces
  File "/srv/homeassistant/lib/python3.5/site-packages/aiohttp/connector.py", line 736, in _create_connection
    traces=None
  File "/srv/homeassistant/lib/python3.5/site-packages/aiohttp/connector.py", line 855, in _create_direct_connection
    raise last_exc
  File "/srv/homeassistant/lib/python3.5/site-packages/aiohttp/connector.py", line 838, in _create_direct_connection
    req=req, client_error=client_error)
  File "/srv/homeassistant/lib/python3.5/site-packages/aiohttp/connector.py", line 807, in _wrap_create_connection
    raise client_error(req.connection_key, exc) from exc
aiohttp.client_exceptions.ClientConnectorError: Cannot connect to host 192.168.1.193:8060 ssl:False [Connect call failed ('192.168.1.193', 8060)]
2018-03-18 10:05:34 ERROR (MainThread) [aiohttp.server] Error handling request
Traceback (most recent call last):
  File "/srv/homeassistant/lib/python3.5/site-packages/aiohttp/connector.py", line 800, in _wrap_create_connection
    return await self._loop.create_connection(*args, **kwargs)
  File "/usr/lib/python3.5/asyncio/base_events.py", line 775, in create_connection
    raise exceptions[0]
  File "/usr/lib/python3.5/asyncio/base_events.py", line 762, in create_connection
    yield from self.sock_connect(sock, address)
  File "/usr/lib/python3.5/asyncio/selector_events.py", line 451, in sock_connect
    return (yield from fut)
  File "/usr/lib/python3.5/asyncio/futures.py", line 380, in __iter__
    yield self  # This tells Task to wait for completion.
  File "/usr/lib/python3.5/asyncio/tasks.py", line 304, in _wakeup
    future.result()
  File "/usr/lib/python3.5/asyncio/futures.py", line 293, in result
    raise self._exception
  File "/usr/lib/python3.5/asyncio/selector_events.py", line 481, in _sock_connect_cb
    raise OSError(err, 'Connect call failed %s' % (address,))
OSError: [Errno 113] Connect call failed ('192.168.1.193', 8060)

The above exception was the direct cause of the following exception:

Traceback (most recent call last):
  File "/srv/homeassistant/lib/python3.5/site-packages/aiohttp/web_protocol.py", line 381, in start
    resp = await self._request_handler(request)
  File "/srv/homeassistant/lib/python3.5/site-packages/aiohttp/web_app.py", line 310, in _handle
    resp = await handler(request)
  File "/srv/homeassistant/lib/python3.5/site-packages/aiohttp/web_middlewares.py", line 88, in impl
    return await handler(request)
  File "/srv/homeassistant/lib/python3.5/site-packages/homeassistant/components/http/static.py", line 68, in staticresource_middleware
    return await handler(request)
  File "/srv/homeassistant/lib/python3.5/site-packages/homeassistant/components/http/real_ip.py", line 27, in real_ip_middleware
    return await handler(request)
  File "/srv/homeassistant/lib/python3.5/site-packages/homeassistant/components/http/ban.py", line 68, in ban_middleware
    return await handler(request)
  File "/srv/homeassistant/lib/python3.5/site-packages/homeassistant/components/http/auth.py", line 28, in auth_middleware
    return await handler(request)
  File "/srv/homeassistant/lib/python3.5/site-packages/homeassistant/components/http/view.py", line 100, in handle
    result = await result
  File "/srv/homeassistant/lib/python3.5/site-packages/homeassistant/components/media_player/__init__.py", line 944, in get
    data, content_type = yield from player.async_get_media_image()
  File "/srv/homeassistant/lib/python3.5/site-packages/homeassistant/components/media_player/__init__.py", line 499, in async_get_media_image
    return (yield from _async_fetch_image(self.hass, url))
  File "/srv/homeassistant/lib/python3.5/site-packages/homeassistant/components/media_player/__init__.py", line 901, in _async_fetch_image
    response = yield from websession.get(url)
  File "/srv/homeassistant/lib/python3.5/site-packages/aiohttp/client.py", line 319, in _request
    traces=traces
  File "/srv/homeassistant/lib/python3.5/site-packages/aiohttp/connector.py", line 418, in connect
    traces=traces
  File "/srv/homeassistant/lib/python3.5/site-packages/aiohttp/connector.py", line 736, in _create_connection
    traces=None
  File "/srv/homeassistant/lib/python3.5/site-packages/aiohttp/connector.py", line 855, in _create_direct_connection
    raise last_exc
  File "/srv/homeassistant/lib/python3.5/site-packages/aiohttp/connector.py", line 838, in _create_direct_connection
    req=req, client_error=client_error)
  File "/srv/homeassistant/lib/python3.5/site-packages/aiohttp/connector.py", line 807, in _wrap_create_connection
    raise client_error(req.connection_key, exc) from exc
aiohttp.client_exceptions.ClientConnectorError: Cannot connect to host 192.168.1.193:8060 ssl:False [Connect call failed ('192.168.1.193', 8060)]
2018-03-18 10:06:34 ERROR (MainThread) [aiohttp.server] Error handling request
Traceback (most recent call last):
  File "/srv/homeassistant/lib/python3.5/site-packages/aiohttp/connector.py", line 800, in _wrap_create_connection
    return await self._loop.create_connection(*args, **kwargs)
  File "/usr/lib/python3.5/asyncio/base_events.py", line 775, in create_connection
    raise exceptions[0]
  File "/usr/lib/python3.5/asyncio/base_events.py", line 762, in create_connection
    yield from self.sock_connect(sock, address)
  File "/usr/lib/python3.5/asyncio/selector_events.py", line 451, in sock_connect
    return (yield from fut)
  File "/usr/lib/python3.5/asyncio/futures.py", line 380, in __iter__
    yield self  # This tells Task to wait for completion.
  File "/usr/lib/python3.5/asyncio/tasks.py", line 304, in _wakeup
    future.result()
  File "/usr/lib/python3.5/asyncio/futures.py", line 293, in result
    raise self._exception
  File "/usr/lib/python3.5/asyncio/selector_events.py", line 481, in _sock_connect_cb
    raise OSError(err, 'Connect call failed %s' % (address,))
OSError: [Errno 113] Connect call failed ('192.168.1.193', 8060)

The above exception was the direct cause of the following exception:

Traceback (most recent call last):
  File "/srv/homeassistant/lib/python3.5/site-packages/aiohttp/web_protocol.py", line 381, in start
    resp = await self._request_handler(request)
  File "/srv/homeassistant/lib/python3.5/site-packages/aiohttp/web_app.py", line 310, in _handle
    resp = await handler(request)
  File "/srv/homeassistant/lib/python3.5/site-packages/aiohttp/web_middlewares.py", line 88, in impl
    return await handler(request)
  File "/srv/homeassistant/lib/python3.5/site-packages/homeassistant/components/http/static.py", line 68, in staticresource_middleware
    return await handler(request)
  File "/srv/homeassistant/lib/python3.5/site-packages/homeassistant/components/http/real_ip.py", line 27, in real_ip_middleware
    return await handler(request)
  File "/srv/homeassistant/lib/python3.5/site-packages/homeassistant/components/http/ban.py", line 68, in ban_middleware
    return await handler(request)
  File "/srv/homeassistant/lib/python3.5/site-packages/homeassistant/components/http/auth.py", line 28, in auth_middleware
    return await handler(request)
  File "/srv/homeassistant/lib/python3.5/site-packages/homeassistant/components/http/view.py", line 100, in handle
    result = await result
  File "/srv/homeassistant/lib/python3.5/site-packages/homeassistant/components/media_player/__init__.py", line 944, in get
    data, content_type = yield from player.async_get_media_image()
  File "/srv/homeassistant/lib/python3.5/site-packages/homeassistant/components/media_player/__init__.py", line 499, in async_get_media_image
    return (yield from _async_fetch_image(self.hass, url))
  File "/srv/homeassistant/lib/python3.5/site-packages/homeassistant/components/media_player/__init__.py", line 901, in _async_fetch_image
    response = yield from websession.get(url)
  File "/srv/homeassistant/lib/python3.5/site-packages/aiohttp/client.py", line 319, in _request
    traces=traces
  File "/srv/homeassistant/lib/python3.5/site-packages/aiohttp/connector.py", line 418, in connect
    traces=traces
  File "/srv/homeassistant/lib/python3.5/site-packages/aiohttp/connector.py", line 736, in _create_connection
    traces=None
  File "/srv/homeassistant/lib/python3.5/site-packages/aiohttp/connector.py", line 855, in _create_direct_connection
    raise last_exc
  File "/srv/homeassistant/lib/python3.5/site-packages/aiohttp/connector.py", line 838, in _create_direct_connection
    req=req, client_error=client_error)
  File "/srv/homeassistant/lib/python3.5/site-packages/aiohttp/connector.py", line 807, in _wrap_create_connection
    raise client_error(req.connection_key, exc) from exc
aiohttp.client_exceptions.ClientConnectorError: Cannot connect to host 192.168.1.193:8060 ssl:False [Connect call failed ('192.168.1.193', 8060)]
2018-03-18 10:07:32 ERROR (MainThread) [aiohttp.server] Error handling request
Traceback (most recent call last):
  File "/srv/homeassistant/lib/python3.5/site-packages/aiohttp/connector.py", line 800, in _wrap_create_connection
    return await self._loop.create_connection(*args, **kwargs)
  File "/usr/lib/python3.5/asyncio/base_events.py", line 775, in create_connection
    raise exceptions[0]
  File "/usr/lib/python3.5/asyncio/base_events.py", line 762, in create_connection
    yield from self.sock_connect(sock, address)
  File "/usr/lib/python3.5/asyncio/selector_events.py", line 451, in sock_connect
    return (yield from fut)
  File "/usr/lib/python3.5/asyncio/futures.py", line 380, in __iter__
    yield self  # This tells Task to wait for completion.
  File "/usr/lib/python3.5/asyncio/tasks.py", line 304, in _wakeup
    future.result()
  File "/usr/lib/python3.5/asyncio/futures.py", line 293, in result
    raise self._exception
  File "/usr/lib/python3.5/asyncio/selector_events.py", line 481, in _sock_connect_cb
    raise OSError(err, 'Connect call failed %s' % (address,))
OSError: [Errno 113] Connect call failed ('192.168.1.193', 8060)

The above exception was the direct cause of the following exception:

Traceback (most recent call last):
  File "/srv/homeassistant/lib/python3.5/site-packages/aiohttp/web_protocol.py", line 381, in start
    resp = await self._request_handler(request)
  File "/srv/homeassistant/lib/python3.5/site-packages/aiohttp/web_app.py", line 310, in _handle
    resp = await handler(request)
  File "/srv/homeassistant/lib/python3.5/site-packages/aiohttp/web_middlewares.py", line 88, in impl
    return await handler(request)
  File "/srv/homeassistant/lib/python3.5/site-packages/homeassistant/components/http/static.py", line 68, in staticresource_middleware
    return await handler(request)
  File "/srv/homeassistant/lib/python3.5/site-packages/homeassistant/components/http/real_ip.py", line 27, in real_ip_middleware
    return await handler(request)
  File "/srv/homeassistant/lib/python3.5/site-packages/homeassistant/components/http/ban.py", line 68, in ban_middleware
    return await handler(request)
  File "/srv/homeassistant/lib/python3.5/site-packages/homeassistant/components/http/auth.py", line 28, in auth_middleware
    return await handler(request)
  File "/srv/homeassistant/lib/python3.5/site-packages/homeassistant/components/http/view.py", line 100, in handle
    result = await result
  File "/srv/homeassistant/lib/python3.5/site-packages/homeassistant/components/media_player/__init__.py", line 944, in get
    data, content_type = yield from player.async_get_media_image()
  File "/srv/homeassistant/lib/python3.5/site-packages/homeassistant/components/media_player/__init__.py", line 499, in async_get_media_image
    return (yield from _async_fetch_image(self.hass, url))
  File "/srv/homeassistant/lib/python3.5/site-packages/homeassistant/components/media_player/__init__.py", line 901, in _async_fetch_image
    response = yield from websession.get(url)
  File "/srv/homeassistant/lib/python3.5/site-packages/aiohttp/client.py", line 319, in _request
    traces=traces
  File "/srv/homeassistant/lib/python3.5/site-packages/aiohttp/connector.py", line 418, in connect
    traces=traces
  File "/srv/homeassistant/lib/python3.5/site-packages/aiohttp/connector.py", line 736, in _create_connection
    traces=None
  File "/srv/homeassistant/lib/python3.5/site-packages/aiohttp/connector.py", line 855, in _create_direct_connection
    raise last_exc
  File "/srv/homeassistant/lib/python3.5/site-packages/aiohttp/connector.py", line 838, in _create_direct_connection
    req=req, client_error=client_error)
  File "/srv/homeassistant/lib/python3.5/site-packages/aiohttp/connector.py", line 807, in _wrap_create_connection
    raise client_error(req.connection_key, exc) from exc
aiohttp.client_exceptions.ClientConnectorError: Cannot connect to host 192.168.1.193:8060 ssl:False [Connect call failed ('192.168.1.193', 8060)]
2018-03-18 10:08:34 ERROR (MainThread) [aiohttp.server] Error handling request
Traceback (most recent call last):
  File "/srv/homeassistant/lib/python3.5/site-packages/aiohttp/connector.py", line 800, in _wrap_create_connection
    return await self._loop.create_connection(*args, **kwargs)
  File "/usr/lib/python3.5/asyncio/base_events.py", line 775, in create_connection
    raise exceptions[0]
  File "/usr/lib/python3.5/asyncio/base_events.py", line 762, in create_connection
    yield from self.sock_connect(sock, address)
  File "/usr/lib/python3.5/asyncio/selector_events.py", line 451, in sock_connect
    return (yield from fut)
  File "/usr/lib/python3.5/asyncio/futures.py", line 380, in __iter__
    yield self  # This tells Task to wait for completion.
  File "/usr/lib/python3.5/asyncio/tasks.py", line 304, in _wakeup
    future.result()
  File "/usr/lib/python3.5/asyncio/futures.py", line 293, in result
    raise self._exception
  File "/usr/lib/python3.5/asyncio/selector_events.py", line 481, in _sock_connect_cb
    raise OSError(err, 'Connect call failed %s' % (address,))
OSError: [Errno 113] Connect call failed ('192.168.1.193', 8060)

The above exception was the direct cause of the following exception:

Traceback (most recent call last):
  File "/srv/homeassistant/lib/python3.5/site-packages/aiohttp/web_protocol.py", line 381, in start
    resp = await self._request_handler(request)
  File "/srv/homeassistant/lib/python3.5/site-packages/aiohttp/web_app.py", line 310, in _handle
    resp = await handler(request)
  File "/srv/homeassistant/lib/python3.5/site-packages/aiohttp/web_middlewares.py", line 88, in impl
    return await handler(request)
  File "/srv/homeassistant/lib/python3.5/site-packages/homeassistant/components/http/static.py", line 68, in staticresource_middleware
    return await handler(request)
  File "/srv/homeassistant/lib/python3.5/site-packages/homeassistant/components/http/real_ip.py", line 27, in real_ip_middleware
    return await handler(request)
  File "/srv/homeassistant/lib/python3.5/site-packages/homeassistant/components/http/ban.py", line 68, in ban_middleware
    return await handler(request)
  File "/srv/homeassistant/lib/python3.5/site-packages/homeassistant/components/http/auth.py", line 28, in auth_middleware
    return await handler(request)
  File "/srv/homeassistant/lib/python3.5/site-packages/homeassistant/components/http/view.py", line 100, in handle
    result = await result
  File "/srv/homeassistant/lib/python3.5/site-packages/homeassistant/components/media_player/__init__.py", line 944, in get
    data, content_type = yield from player.async_get_media_image()
  File "/srv/homeassistant/lib/python3.5/site-packages/homeassistant/components/media_player/__init__.py", line 499, in async_get_media_image
    return (yield from _async_fetch_image(self.hass, url))
  File "/srv/homeassistant/lib/python3.5/site-packages/homeassistant/components/media_player/__init__.py", line 901, in _async_fetch_image
    response = yield from websession.get(url)
  File "/srv/homeassistant/lib/python3.5/site-packages/aiohttp/client.py", line 319, in _request
    traces=traces
  File "/srv/homeassistant/lib/python3.5/site-packages/aiohttp/connector.py", line 418, in connect
    traces=traces
  File "/srv/homeassistant/lib/python3.5/site-packages/aiohttp/connector.py", line 736, in _create_connection
    traces=None
  File "/srv/homeassistant/lib/python3.5/site-packages/aiohttp/connector.py", line 855, in _create_direct_connection
    raise last_exc
  File "/srv/homeassistant/lib/python3.5/site-packages/aiohttp/connector.py", line 838, in _create_direct_connection
    req=req, client_error=client_error)
  File "/srv/homeassistant/lib/python3.5/site-packages/aiohttp/connector.py", line 807, in _wrap_create_connection
    raise client_error(req.connection_key, exc) from exc
aiohttp.client_exceptions.ClientConnectorError: Cannot connect to host 192.168.1.193:8060 ssl:False [Connect call failed ('192.168.1.193', 8060)]
2018-03-18 10:09:33 ERROR (MainThread) [aiohttp.server] Error handling request
Traceback (most recent call last):
  File "/srv/homeassistant/lib/python3.5/site-packages/aiohttp/connector.py", line 800, in _wrap_create_connection
    return await self._loop.create_connection(*args, **kwargs)
  File "/usr/lib/python3.5/asyncio/base_events.py", line 775, in create_connection
    raise exceptions[0]
  File "/usr/lib/python3.5/asyncio/base_events.py", line 762, in create_connection
    yield from self.sock_connect(sock, address)
  File "/usr/lib/python3.5/asyncio/selector_events.py", line 451, in sock_connect
    return (yield from fut)
  File "/usr/lib/python3.5/asyncio/futures.py", line 380, in __iter__
    yield self  # This tells Task to wait for completion.
  File "/usr/lib/python3.5/asyncio/tasks.py", line 304, in _wakeup
    future.result()
  File "/usr/lib/python3.5/asyncio/futures.py", line 293, in result
    raise self._exception
  File "/usr/lib/python3.5/asyncio/selector_events.py", line 481, in _sock_connect_cb
    raise OSError(err, 'Connect call failed %s' % (address,))
OSError: [Errno 113] Connect call failed ('192.168.1.193', 8060)

The above exception was the direct cause of the following exception:

Traceback (most recent call last):
  File "/srv/homeassistant/lib/python3.5/site-packages/aiohttp/web_protocol.py", line 381, in start
    resp = await self._request_handler(request)
  File "/srv/homeassistant/lib/python3.5/site-packages/aiohttp/web_app.py", line 310, in _handle
    resp = await handler(request)
  File "/srv/homeassistant/lib/python3.5/site-packages/aiohttp/web_middlewares.py", line 88, in impl
    return await handler(request)
  File "/srv/homeassistant/lib/python3.5/site-packages/homeassistant/components/http/static.py", line 68, in staticresource_middleware
    return await handler(request)
  File "/srv/homeassistant/lib/python3.5/site-packages/homeassistant/components/http/real_ip.py", line 27, in real_ip_middleware
    return await handler(request)
  File "/srv/homeassistant/lib/python3.5/site-packages/homeassistant/components/http/ban.py", line 68, in ban_middleware
    return await handler(request)
  File "/srv/homeassistant/lib/python3.5/site-packages/homeassistant/components/http/auth.py", line 28, in auth_middleware
    return await handler(request)
  File "/srv/homeassistant/lib/python3.5/site-packages/homeassistant/components/http/view.py", line 100, in handle
    result = await result
  File "/srv/homeassistant/lib/python3.5/site-packages/homeassistant/components/media_player/__init__.py", line 944, in get
    data, content_type = yield from player.async_get_media_image()
  File "/srv/homeassistant/lib/python3.5/site-packages/homeassistant/components/media_player/__init__.py", line 499, in async_get_media_image
    return (yield from _async_fetch_image(self.hass, url))
  File "/srv/homeassistant/lib/python3.5/site-packages/homeassistant/components/media_player/__init__.py", line 901, in _async_fetch_image
    response = yield from websession.get(url)
  File "/srv/homeassistant/lib/python3.5/site-packages/aiohttp/client.py", line 319, in _request
    traces=traces
  File "/srv/homeassistant/lib/python3.5/site-packages/aiohttp/connector.py", line 418, in connect
    traces=traces
  File "/srv/homeassistant/lib/python3.5/site-packages/aiohttp/connector.py", line 736, in _create_connection
    traces=None
  File "/srv/homeassistant/lib/python3.5/site-packages/aiohttp/connector.py", line 855, in _create_direct_connection
    raise last_exc
  File "/srv/homeassistant/lib/python3.5/site-packages/aiohttp/connector.py", line 838, in _create_direct_connection
    req=req, client_error=client_error)
  File "/srv/homeassistant/lib/python3.5/site-packages/aiohttp/connector.py", line 807, in _wrap_create_connection
    raise client_error(req.connection_key, exc) from exc
aiohttp.client_exceptions.ClientConnectorError: Cannot connect to host 192.168.1.193:8060 ssl:False [Connect call failed ('192.168.1.193', 8060)]
2018-03-18 10:10:31 ERROR (MainThread) [aiohttp.server] Error handling request
Traceback (most recent call last):
  File "/srv/homeassistant/lib/python3.5/site-packages/aiohttp/connector.py", line 800, in _wrap_create_connection
    return await self._loop.create_connection(*args, **kwargs)
  File "/usr/lib/python3.5/asyncio/base_events.py", line 775, in create_connection
    raise exceptions[0]
  File "/usr/lib/python3.5/asyncio/base_events.py", line 762, in create_connection
    yield from self.sock_connect(sock, address)
  File "/usr/lib/python3.5/asyncio/selector_events.py", line 451, in sock_connect
    return (yield from fut)
  File "/usr/lib/python3.5/asyncio/futures.py", line 380, in __iter__
    yield self  # This tells Task to wait for completion.
  File "/usr/lib/python3.5/asyncio/tasks.py", line 304, in _wakeup
    future.result()
  File "/usr/lib/python3.5/asyncio/futures.py", line 293, in result
    raise self._exception
  File "/usr/lib/python3.5/asyncio/selector_events.py", line 481, in _sock_connect_cb
    raise OSError(err, 'Connect call failed %s' % (address,))
OSError: [Errno 113] Connect call failed ('192.168.1.193', 8060)

The above exception was the direct cause of the following exception:

Traceback (most recent call last):
  File "/srv/homeassistant/lib/python3.5/site-packages/aiohttp/web_protocol.py", line 381, in start
    resp = await self._request_handler(request)
  File "/srv/homeassistant/lib/python3.5/site-packages/aiohttp/web_app.py", line 310, in _handle
    resp = await handler(request)
  File "/srv/homeassistant/lib/python3.5/site-packages/aiohttp/web_middlewares.py", line 88, in impl
    return await handler(request)
  File "/srv/homeassistant/lib/python3.5/site-packages/homeassistant/components/http/static.py", line 68, in staticresource_middleware
    return await handler(request)
  File "/srv/homeassistant/lib/python3.5/site-packages/homeassistant/components/http/real_ip.py", line 27, in real_ip_middleware
    return await handler(request)
  File "/srv/homeassistant/lib/python3.5/site-packages/homeassistant/components/http/ban.py", line 68, in ban_middleware
    return await handler(request)
  File "/srv/homeassistant/lib/python3.5/site-packages/homeassistant/components/http/auth.py", line 28, in auth_middleware
    return await handler(request)
  File "/srv/homeassistant/lib/python3.5/site-packages/homeassistant/components/http/view.py", line 100, in handle
    result = await result
  File "/srv/homeassistant/lib/python3.5/site-packages/homeassistant/components/media_player/__init__.py", line 944, in get
    data, content_type = yield from player.async_get_media_image()
  File "/srv/homeassistant/lib/python3.5/site-packages/homeassistant/components/media_player/__init__.py", line 499, in async_get_media_image
    return (yield from _async_fetch_image(self.hass, url))
  File "/srv/homeassistant/lib/python3.5/site-packages/homeassistant/components/media_player/__init__.py", line 901, in _async_fetch_image
    response = yield from websession.get(url)
  File "/srv/homeassistant/lib/python3.5/site-packages/aiohttp/client.py", line 319, in _request
    traces=traces
  File "/srv/homeassistant/lib/python3.5/site-packages/aiohttp/connector.py", line 418, in connect
    traces=traces
  File "/srv/homeassistant/lib/python3.5/site-packages/aiohttp/connector.py", line 736, in _create_connection
    traces=None
  File "/srv/homeassistant/lib/python3.5/site-packages/aiohttp/connector.py", line 855, in _create_direct_connection
    raise last_exc
  File "/srv/homeassistant/lib/python3.5/site-packages/aiohttp/connector.py", line 838, in _create_direct_connection
    req=req, client_error=client_error)
  File "/srv/homeassistant/lib/python3.5/site-packages/aiohttp/connector.py", line 807, in _wrap_create_connection
    raise client_error(req.connection_key, exc) from exc
aiohttp.client_exceptions.ClientConnectorError: Cannot connect to host 192.168.1.193:8060 ssl:False [Connect call failed ('192.168.1.193', 8060)]
2018-03-18 10:11:34 ERROR (MainThread) [aiohttp.server] Error handling request
Traceback (most recent call last):
  File "/srv/homeassistant/lib/python3.5/site-packages/aiohttp/connector.py", line 800, in _wrap_create_connection
    return await self._loop.create_connection(*args, **kwargs)
  File "/usr/lib/python3.5/asyncio/base_events.py", line 775, in create_connection
    raise exceptions[0]
  File "/usr/lib/python3.5/asyncio/base_events.py", line 762, in create_connection
    yield from self.sock_connect(sock, address)
  File "/usr/lib/python3.5/asyncio/selector_events.py", line 451, in sock_connect
    return (yield from fut)
  File "/usr/lib/python3.5/asyncio/futures.py", line 380, in __iter__
    yield self  # This tells Task to wait for completion.
  File "/usr/lib/python3.5/asyncio/tasks.py", line 304, in _wakeup
    future.result()
  File "/usr/lib/python3.5/asyncio/futures.py", line 293, in result
    raise self._exception
  File "/usr/lib/python3.5/asyncio/selector_events.py", line 481, in _sock_connect_cb
    raise OSError(err, 'Connect call failed %s' % (address,))
OSError: [Errno 113] Connect call failed ('192.168.1.193', 8060)

The above exception was the direct cause of the following exception:

Traceback (most recent call last):
  File "/srv/homeassistant/lib/python3.5/site-packages/aiohttp/web_protocol.py", line 381, in start
    resp = await self._request_handler(request)
  File "/srv/homeassistant/lib/python3.5/site-packages/aiohttp/web_app.py", line 310, in _handle
    resp = await handler(request)
  File "/srv/homeassistant/lib/python3.5/site-packages/aiohttp/web_middlewares.py", line 88, in impl
    return await handler(request)
  File "/srv/homeassistant/lib/python3.5/site-packages/homeassistant/components/http/static.py", line 68, in staticresource_middleware
    return await handler(request)
  File "/srv/homeassistant/lib/python3.5/site-packages/homeassistant/components/http/real_ip.py", line 27, in real_ip_middleware
    return await handler(request)
  File "/srv/homeassistant/lib/python3.5/site-packages/homeassistant/components/http/ban.py", line 68, in ban_middleware
    return await handler(request)
  File "/srv/homeassistant/lib/python3.5/site-packages/homeassistant/components/http/auth.py", line 28, in auth_middleware
    return await handler(request)
  File "/srv/homeassistant/lib/python3.5/site-packages/homeassistant/components/http/view.py", line 100, in handle
    result = await result
  File "/srv/homeassistant/lib/python3.5/site-packages/homeassistant/components/media_player/__init__.py", line 944, in get
    data, content_type = yield from player.async_get_media_image()
  File "/srv/homeassistant/lib/python3.5/site-packages/homeassistant/components/media_player/__init__.py", line 499, in async_get_media_image
    return (yield from _async_fetch_image(self.hass, url))
  File "/srv/homeassistant/lib/python3.5/site-packages/homeassistant/components/media_player/__init__.py", line 901, in _async_fetch_image
    response = yield from websession.get(url)
  File "/srv/homeassistant/lib/python3.5/site-packages/aiohttp/client.py", line 319, in _request
    traces=traces
  File "/srv/homeassistant/lib/python3.5/site-packages/aiohttp/connector.py", line 418, in connect
    traces=traces
  File "/srv/homeassistant/lib/python3.5/site-packages/aiohttp/connector.py", line 736, in _create_connection
    traces=None
  File "/srv/homeassistant/lib/python3.5/site-packages/aiohttp/connector.py", line 855, in _create_direct_connection
    raise last_exc
  File "/srv/homeassistant/lib/python3.5/site-packages/aiohttp/connector.py", line 838, in _create_direct_connection
    req=req, client_error=client_error)
  File "/srv/homeassistant/lib/python3.5/site-packages/aiohttp/connector.py", line 807, in _wrap_create_connection
    raise client_error(req.connection_key, exc) from exc
aiohttp.client_exceptions.ClientConnectorError: Cannot connect to host 192.168.1.193:8060 ssl:False [Connect call failed ('192.168.1.193', 8060)]
2018-03-18 10:12:32 ERROR (MainThread) [aiohttp.server] Error handling request
Traceback (most recent call last):
  File "/srv/homeassistant/lib/python3.5/site-packages/aiohttp/connector.py", line 800, in _wrap_create_connection
    return await self._loop.create_connection(*args, **kwargs)
  File "/usr/lib/python3.5/asyncio/base_events.py", line 775, in create_connection
    raise exceptions[0]
  File "/usr/lib/python3.5/asyncio/base_events.py", line 762, in create_connection
    yield from self.sock_connect(sock, address)
  File "/usr/lib/python3.5/asyncio/selector_events.py", line 451, in sock_connect
    return (yield from fut)
  File "/usr/lib/python3.5/asyncio/futures.py", line 380, in __iter__
    yield self  # This tells Task to wait for completion.
  File "/usr/lib/python3.5/asyncio/tasks.py", line 304, in _wakeup
    future.result()
  File "/usr/lib/python3.5/asyncio/futures.py", line 293, in result
    raise self._exception
  File "/usr/lib/python3.5/asyncio/selector_events.py", line 481, in _sock_connect_cb
    raise OSError(err, 'Connect call failed %s' % (address,))
OSError: [Errno 113] Connect call failed ('192.168.1.193', 8060)

The above exception was the direct cause of the following exception:

Traceback (most recent call last):
  File "/srv/homeassistant/lib/python3.5/site-packages/aiohttp/web_protocol.py", line 381, in start
    resp = await self._request_handler(request)
  File "/srv/homeassistant/lib/python3.5/site-packages/aiohttp/web_app.py", line 310, in _handle
    resp = await handler(request)
  File "/srv/homeassistant/lib/python3.5/site-packages/aiohttp/web_middlewares.py", line 88, in impl
    return await handler(request)
  File "/srv/homeassistant/lib/python3.5/site-packages/homeassistant/components/http/static.py", line 68, in staticresource_middleware
    return await handler(request)
  File "/srv/homeassistant/lib/python3.5/site-packages/homeassistant/components/http/real_ip.py", line 27, in real_ip_middleware
    return await handler(request)
  File "/srv/homeassistant/lib/python3.5/site-packages/homeassistant/components/http/ban.py", line 68, in ban_middleware
    return await handler(request)
  File "/srv/homeassistant/lib/python3.5/site-packages/homeassistant/components/http/auth.py", line 28, in auth_middleware
    return await handler(request)
  File "/srv/homeassistant/lib/python3.5/site-packages/homeassistant/components/http/view.py", line 100, in handle
    result = await result
  File "/srv/homeassistant/lib/python3.5/site-packages/homeassistant/components/media_player/__init__.py", line 944, in get
    data, content_type = yield from player.async_get_media_image()
  File "/srv/homeassistant/lib/python3.5/site-packages/homeassistant/components/media_player/__init__.py", line 499, in async_get_media_image
    return (yield from _async_fetch_image(self.hass, url))
  File "/srv/homeassistant/lib/python3.5/site-packages/homeassistant/components/media_player/__init__.py", line 901, in _async_fetch_image
    response = yield from websession.get(url)
  File "/srv/homeassistant/lib/python3.5/site-packages/aiohttp/client.py", line 319, in _request
    traces=traces
  File "/srv/homeassistant/lib/python3.5/site-packages/aiohttp/connector.py", line 418, in connect
    traces=traces
  File "/srv/homeassistant/lib/python3.5/site-packages/aiohttp/connector.py", line 736, in _create_connection
    traces=None
  File "/srv/homeassistant/lib/python3.5/site-packages/aiohttp/connector.py", line 855, in _create_direct_connection
    raise last_exc
  File "/srv/homeassistant/lib/python3.5/site-packages/aiohttp/connector.py", line 838, in _create_direct_connection
    req=req, client_error=client_error)
  File "/srv/homeassistant/lib/python3.5/site-packages/aiohttp/connector.py", line 807, in _wrap_create_connection
    raise client_error(req.connection_key, exc) from exc
aiohttp.client_exceptions.ClientConnectorError: Cannot connect to host 192.168.1.193:8060 ssl:False [Connect call failed ('192.168.1.193', 8060)]
2018-03-18 10:13:34 ERROR (MainThread) [aiohttp.server] Error handling request
Traceback (most recent call last):
  File "/srv/homeassistant/lib/python3.5/site-packages/aiohttp/connector.py", line 800, in _wrap_create_connection
    return await self._loop.create_connection(*args, **kwargs)
  File "/usr/lib/python3.5/asyncio/base_events.py", line 775, in create_connection
    raise exceptions[0]
  File "/usr/lib/python3.5/asyncio/base_events.py", line 762, in create_connection
    yield from self.sock_connect(sock, address)
  File "/usr/lib/python3.5/asyncio/selector_events.py", line 451, in sock_connect
    return (yield from fut)
  File "/usr/lib/python3.5/asyncio/futures.py", line 380, in __iter__
    yield self  # This tells Task to wait for completion.
  File "/usr/lib/python3.5/asyncio/tasks.py", line 304, in _wakeup
    future.result()
  File "/usr/lib/python3.5/asyncio/futures.py", line 293, in result
    raise self._exception
  File "/usr/lib/python3.5/asyncio/selector_events.py", line 481, in _sock_connect_cb
    raise OSError(err, 'Connect call failed %s' % (address,))
OSError: [Errno 113] Connect call failed ('192.168.1.193', 8060)

The above exception was the direct cause of the following exception:

Traceback (most recent call last):
  File "/srv/homeassistant/lib/python3.5/site-packages/aiohttp/web_protocol.py", line 381, in start
    resp = await self._request_handler(request)
  File "/srv/homeassistant/lib/python3.5/site-packages/aiohttp/web_app.py", line 310, in _handle
    resp = await handler(request)
  File "/srv/homeassistant/lib/python3.5/site-packages/aiohttp/web_middlewares.py", line 88, in impl
    return await handler(request)
  File "/srv/homeassistant/lib/python3.5/site-packages/homeassistant/components/http/static.py", line 68, in staticresource_middleware
    return await handler(request)
  File "/srv/homeassistant/lib/python3.5/site-packages/homeassistant/components/http/real_ip.py", line 27, in real_ip_middleware
    return await handler(request)
  File "/srv/homeassistant/lib/python3.5/site-packages/homeassistant/components/http/ban.py", line 68, in ban_middleware
    return await handler(request)
  File "/srv/homeassistant/lib/python3.5/site-packages/homeassistant/components/http/auth.py", line 28, in auth_middleware
    return await handler(request)
  File "/srv/homeassistant/lib/python3.5/site-packages/homeassistant/components/http/view.py", line 100, in handle
    result = await result
  File "/srv/homeassistant/lib/python3.5/site-packages/homeassistant/components/media_player/__init__.py", line 944, in get
    data, content_type = yield from player.async_get_media_image()
  File "/srv/homeassistant/lib/python3.5/site-packages/homeassistant/components/media_player/__init__.py", line 499, in async_get_media_image
    return (yield from _async_fetch_image(self.hass, url))
  File "/srv/homeassistant/lib/python3.5/site-packages/homeassistant/components/media_player/__init__.py", line 901, in _async_fetch_image
    response = yield from websession.get(url)
  File "/srv/homeassistant/lib/python3.5/site-packages/aiohttp/client.py", line 319, in _request
    traces=traces
  File "/srv/homeassistant/lib/python3.5/site-packages/aiohttp/connector.py", line 418, in connect
    traces=traces
  File "/srv/homeassistant/lib/python3.5/site-packages/aiohttp/connector.py", line 736, in _create_connection
    traces=None
  File "/srv/homeassistant/lib/python3.5/site-packages/aiohttp/connector.py", line 855, in _create_direct_connection
    raise last_exc
  File "/srv/homeassistant/lib/python3.5/site-packages/aiohttp/connector.py", line 838, in _create_direct_connection
    req=req, client_error=client_error)
  File "/srv/homeassistant/lib/python3.5/site-packages/aiohttp/connector.py", line 807, in _wrap_create_connection
    raise client_error(req.connection_key, exc) from exc
aiohttp.client_exceptions.ClientConnectorError: Cannot connect to host 192.168.1.193:8060 ssl:False [Connect call failed ('192.168.1.193', 8060)]
2018-03-18 10:14:33 ERROR (MainThread) [aiohttp.server] Error handling request
Traceback (most recent call last):
  File "/srv/homeassistant/lib/python3.5/site-packages/aiohttp/connector.py", line 800, in _wrap_create_connection
    return await self._loop.create_connection(*args, **kwargs)
  File "/usr/lib/python3.5/asyncio/base_events.py", line 775, in create_connection
    raise exceptions[0]
  File "/usr/lib/python3.5/asyncio/base_events.py", line 762, in create_connection
    yield from self.sock_connect(sock, address)
  File "/usr/lib/python3.5/asyncio/selector_events.py", line 451, in sock_connect
    return (yield from fut)
  File "/usr/lib/python3.5/asyncio/futures.py", line 380, in __iter__
    yield self  # This tells Task to wait for completion.
  File "/usr/lib/python3.5/asyncio/tasks.py", line 304, in _wakeup
    future.result()
  File "/usr/lib/python3.5/asyncio/futures.py", line 293, in result
    raise self._exception
  File "/usr/lib/python3.5/asyncio/selector_events.py", line 481, in _sock_connect_cb
    raise OSError(err, 'Connect call failed %s' % (address,))
OSError: [Errno 113] Connect call failed ('192.168.1.193', 8060)

The above exception was the direct cause of the following exception:

Traceback (most recent call last):
  File "/srv/homeassistant/lib/python3.5/site-packages/aiohttp/web_protocol.py", line 381, in start
    resp = await self._request_handler(request)
  File "/srv/homeassistant/lib/python3.5/site-packages/aiohttp/web_app.py", line 310, in _handle
    resp = await handler(request)
  File "/srv/homeassistant/lib/python3.5/site-packages/aiohttp/web_middlewares.py", line 88, in impl
    return await handler(request)
  File "/srv/homeassistant/lib/python3.5/site-packages/homeassistant/components/http/static.py", line 68, in staticresource_middleware
    return await handler(request)
  File "/srv/homeassistant/lib/python3.5/site-packages/homeassistant/components/http/real_ip.py", line 27, in real_ip_middleware
    return await handler(request)
  File "/srv/homeassistant/lib/python3.5/site-packages/homeassistant/components/http/ban.py", line 68, in ban_middleware
    return await handler(request)
  File "/srv/homeassistant/lib/python3.5/site-packages/homeassistant/components/http/auth.py", line 28, in auth_middleware
    return await handler(request)
  File "/srv/homeassistant/lib/python3.5/site-packages/homeassistant/components/http/view.py", line 100, in handle
    result = await result
  File "/srv/homeassistant/lib/python3.5/site-packages/homeassistant/components/media_player/__init__.py", line 944, in get
    data, content_type = yield from player.async_get_media_image()
  File "/srv/homeassistant/lib/python3.5/site-packages/homeassistant/components/media_player/__init__.py", line 499, in async_get_media_image
    return (yield from _async_fetch_image(self.hass, url))
  File "/srv/homeassistant/lib/python3.5/site-packages/homeassistant/components/media_player/__init__.py", line 901, in _async_fetch_image
    response = yield from websession.get(url)
  File "/srv/homeassistant/lib/python3.5/site-packages/aiohttp/client.py", line 319, in _request
    traces=traces
  File "/srv/homeassistant/lib/python3.5/site-packages/aiohttp/connector.py", line 418, in connect
    traces=traces
  File "/srv/homeassistant/lib/python3.5/site-packages/aiohttp/connector.py", line 736, in _create_connection
    traces=None
  File "/srv/homeassistant/lib/python3.5/site-packages/aiohttp/connector.py", line 855, in _create_direct_connection
    raise last_exc
  File "/srv/homeassistant/lib/python3.5/site-packages/aiohttp/connector.py", line 838, in _create_direct_connection
    req=req, client_error=client_error)
  File "/srv/homeassistant/lib/python3.5/site-packages/aiohttp/connector.py", line 807, in _wrap_create_connection
    raise client_error(req.connection_key, exc) from exc
aiohttp.client_exceptions.ClientConnectorError: Cannot connect to host 192.168.1.193:8060 ssl:False [Connect call failed ('192.168.1.193', 8060)]
2018-03-18 10:15:35 ERROR (MainThread) [aiohttp.server] Error handling request
Traceback (most recent call last):
  File "/srv/homeassistant/lib/python3.5/site-packages/aiohttp/connector.py", line 800, in _wrap_create_connection
    return await self._loop.create_connection(*args, **kwargs)
  File "/usr/lib/python3.5/asyncio/base_events.py", line 775, in create_connection
    raise exceptions[0]
  File "/usr/lib/python3.5/asyncio/base_events.py", line 762, in create_connection
    yield from self.sock_connect(sock, address)
  File "/usr/lib/python3.5/asyncio/selector_events.py", line 451, in sock_connect
    return (yield from fut)
  File "/usr/lib/python3.5/asyncio/futures.py", line 380, in __iter__
    yield self  # This tells Task to wait for completion.
  File "/usr/lib/python3.5/asyncio/tasks.py", line 304, in _wakeup
    future.result()
  File "/usr/lib/python3.5/asyncio/futures.py", line 293, in result
    raise self._exception
  File "/usr/lib/python3.5/asyncio/selector_events.py", line 481, in _sock_connect_cb
    raise OSError(err, 'Connect call failed %s' % (address,))
OSError: [Errno 113] Connect call failed ('192.168.1.193', 8060)

The above exception was the direct cause of the following exception:

Traceback (most recent call last):
  File "/srv/homeassistant/lib/python3.5/site-packages/aiohttp/web_protocol.py", line 381, in start
    resp = await self._request_handler(request)
  File "/srv/homeassistant/lib/python3.5/site-packages/aiohttp/web_app.py", line 310, in _handle
    resp = await handler(request)
  File "/srv/homeassistant/lib/python3.5/site-packages/aiohttp/web_middlewares.py", line 88, in impl
    return await handler(request)
  File "/srv/homeassistant/lib/python3.5/site-packages/homeassistant/components/http/static.py", line 68, in staticresource_middleware
    return await handler(request)
  File "/srv/homeassistant/lib/python3.5/site-packages/homeassistant/components/http/real_ip.py", line 27, in real_ip_middleware
    return await handler(request)
  File "/srv/homeassistant/lib/python3.5/site-packages/homeassistant/components/http/ban.py", line 68, in ban_middleware
    return await handler(request)
  File "/srv/homeassistant/lib/python3.5/site-packages/homeassistant/components/http/auth.py", line 28, in auth_middleware
    return await handler(request)
  File "/srv/homeassistant/lib/python3.5/site-packages/homeassistant/components/http/view.py", line 100, in handle
    result = await result
  File "/srv/homeassistant/lib/python3.5/site-packages/homeassistant/components/media_player/__init__.py", line 944, in get
    data, content_type = yield from player.async_get_media_image()
  File "/srv/homeassistant/lib/python3.5/site-packages/homeassistant/components/media_player/__init__.py", line 499, in async_get_media_image
    return (yield from _async_fetch_image(self.hass, url))
  File "/srv/homeassistant/lib/python3.5/site-packages/homeassistant/components/media_player/__init__.py", line 901, in _async_fetch_image
    response = yield from websession.get(url)
  File "/srv/homeassistant/lib/python3.5/site-packages/aiohttp/client.py", line 319, in _request
    traces=traces
  File "/srv/homeassistant/lib/python3.5/site-packages/aiohttp/connector.py", line 418, in connect
    traces=traces
  File "/srv/homeassistant/lib/python3.5/site-packages/aiohttp/connector.py", line 736, in _create_connection
    traces=None
  File "/srv/homeassistant/lib/python3.5/site-packages/aiohttp/connector.py", line 855, in _create_direct_connection
    raise last_exc
  File "/srv/homeassistant/lib/python3.5/site-packages/aiohttp/connector.py", line 838, in _create_direct_connection
    req=req, client_error=client_error)
  File "/srv/homeassistant/lib/python3.5/site-packages/aiohttp/connector.py", line 807, in _wrap_create_connection
    raise client_error(req.connection_key, exc) from exc
aiohttp.client_exceptions.ClientConnectorError: Cannot connect to host 192.168.1.193:8060 ssl:False [Connect call failed ('192.168.1.193', 8060)]
2018-03-18 10:16:31 ERROR (MainThread) [aiohttp.server] Error handling request
Traceback (most recent call last):
  File "/srv/homeassistant/lib/python3.5/site-packages/aiohttp/connector.py", line 800, in _wrap_create_connection
    return await self._loop.create_connection(*args, **kwargs)
  File "/usr/lib/python3.5/asyncio/base_events.py", line 775, in create_connection
    raise exceptions[0]
  File "/usr/lib/python3.5/asyncio/base_events.py", line 762, in create_connection
    yield from self.sock_connect(sock, address)
  File "/usr/lib/python3.5/asyncio/selector_events.py", line 451, in sock_connect
    return (yield from fut)
  File "/usr/lib/python3.5/asyncio/futures.py", line 380, in __iter__
    yield self  # This tells Task to wait for completion.
  File "/usr/lib/python3.5/asyncio/tasks.py", line 304, in _wakeup
    future.result()
  File "/usr/lib/python3.5/asyncio/futures.py", line 293, in result
    raise self._exception
  File "/usr/lib/python3.5/asyncio/selector_events.py", line 481, in _sock_connect_cb
    raise OSError(err, 'Connect call failed %s' % (address,))
OSError: [Errno 113] Connect call failed ('192.168.1.193', 8060)

The above exception was the direct cause of the following exception:

Traceback (most recent call last):
  File "/srv/homeassistant/lib/python3.5/site-packages/aiohttp/web_protocol.py", line 381, in start
    resp = await self._request_handler(request)
  File "/srv/homeassistant/lib/python3.5/site-packages/aiohttp/web_app.py", line 310, in _handle
    resp = await handler(request)
  File "/srv/homeassistant/lib/python3.5/site-packages/aiohttp/web_middlewares.py", line 88, in impl
    return await handler(request)
  File "/srv/homeassistant/lib/python3.5/site-packages/homeassistant/components/http/static.py", line 68, in staticresource_middleware
    return await handler(request)
  File "/srv/homeassistant/lib/python3.5/site-packages/homeassistant/components/http/real_ip.py", line 27, in real_ip_middleware
    return await handler(request)
  File "/srv/homeassistant/lib/python3.5/site-packages/homeassistant/components/http/ban.py", line 68, in ban_middleware
    return await handler(request)
  File "/srv/homeassistant/lib/python3.5/site-packages/homeassistant/components/http/auth.py", line 28, in auth_middleware
    return await handler(request)
  File "/srv/homeassistant/lib/python3.5/site-packages/homeassistant/components/http/view.py", line 100, in handle
    result = await result
  File "/srv/homeassistant/lib/python3.5/site-packages/homeassistant/components/media_player/__init__.py", line 944, in get
    data, content_type = yield from player.async_get_media_image()
  File "/srv/homeassistant/lib/python3.5/site-packages/homeassistant/components/media_player/__init__.py", line 499, in async_get_media_image
    return (yield from _async_fetch_image(self.hass, url))
  File "/srv/homeassistant/lib/python3.5/site-packages/homeassistant/components/media_player/__init__.py", line 901, in _async_fetch_image
    response = yield from websession.get(url)
  File "/srv/homeassistant/lib/python3.5/site-packages/aiohttp/client.py", line 319, in _request
    traces=traces
  File "/srv/homeassistant/lib/python3.5/site-packages/aiohttp/connector.py", line 418, in connect
    traces=traces
  File "/srv/homeassistant/lib/python3.5/site-packages/aiohttp/connector.py", line 736, in _create_connection
    traces=None
  File "/srv/homeassistant/lib/python3.5/site-packages/aiohttp/connector.py", line 855, in _create_direct_connection
    raise last_exc
  File "/srv/homeassistant/lib/python3.5/site-packages/aiohttp/connector.py", line 838, in _create_direct_connection
    req=req, client_error=client_error)
  File "/srv/homeassistant/lib/python3.5/site-packages/aiohttp/connector.py", line 807, in _wrap_create_connection
    raise client_error(req.connection_key, exc) from exc
aiohttp.client_exceptions.ClientConnectorError: Cannot connect to host 192.168.1.193:8060 ssl:False [Connect call failed ('192.168.1.193', 8060)]
2018-03-18 10:17:35 ERROR (MainThread) [aiohttp.server] Error handling request
Traceback (most recent call last):
  File "/srv/homeassistant/lib/python3.5/site-packages/aiohttp/connector.py", line 800, in _wrap_create_connection
    return await self._loop.create_connection(*args, **kwargs)
  File "/usr/lib/python3.5/asyncio/base_events.py", line 775, in create_connection
    raise exceptions[0]
  File "/usr/lib/python3.5/asyncio/base_events.py", line 762, in create_connection
    yield from self.sock_connect(sock, address)
  File "/usr/lib/python3.5/asyncio/selector_events.py", line 451, in sock_connect
    return (yield from fut)
  File "/usr/lib/python3.5/asyncio/futures.py", line 380, in __iter__
    yield self  # This tells Task to wait for completion.
  File "/usr/lib/python3.5/asyncio/tasks.py", line 304, in _wakeup
    future.result()
  File "/usr/lib/python3.5/asyncio/futures.py", line 293, in result
    raise self._exception
  File "/usr/lib/python3.5/asyncio/selector_events.py", line 481, in _sock_connect_cb
    raise OSError(err, 'Connect call failed %s' % (address,))
OSError: [Errno 113] Connect call failed ('192.168.1.193', 8060)

The above exception was the direct cause of the following exception:

Traceback (most recent call last):
  File "/srv/homeassistant/lib/python3.5/site-packages/aiohttp/web_protocol.py", line 381, in start
    resp = await self._request_handler(request)
  File "/srv/homeassistant/lib/python3.5/site-packages/aiohttp/web_app.py", line 310, in _handle
    resp = await handler(request)
  File "/srv/homeassistant/lib/python3.5/site-packages/aiohttp/web_middlewares.py", line 88, in impl
    return await handler(request)
  File "/srv/homeassistant/lib/python3.5/site-packages/homeassistant/components/http/static.py", line 68, in staticresource_middleware
    return await handler(request)
  File "/srv/homeassistant/lib/python3.5/site-packages/homeassistant/components/http/real_ip.py", line 27, in real_ip_middleware
    return await handler(request)
  File "/srv/homeassistant/lib/python3.5/site-packages/homeassistant/components/http/ban.py", line 68, in ban_middleware
    return await handler(request)
  File "/srv/homeassistant/lib/python3.5/site-packages/homeassistant/components/http/auth.py", line 28, in auth_middleware
    return await handler(request)
  File "/srv/homeassistant/lib/python3.5/site-packages/homeassistant/components/http/view.py", line 100, in handle
    result = await result
  File "/srv/homeassistant/lib/python3.5/site-packages/homeassistant/components/media_player/__init__.py", line 944, in get
    data, content_type = yield from player.async_get_media_image()
  File "/srv/homeassistant/lib/python3.5/site-packages/homeassistant/components/media_player/__init__.py", line 499, in async_get_media_image
    return (yield from _async_fetch_image(self.hass, url))
  File "/srv/homeassistant/lib/python3.5/site-packages/homeassistant/components/media_player/__init__.py", line 901, in _async_fetch_image
    response = yield from websession.get(url)
  File "/srv/homeassistant/lib/python3.5/site-packages/aiohttp/client.py", line 319, in _request
    traces=traces
  File "/srv/homeassistant/lib/python3.5/site-packages/aiohttp/connector.py", line 418, in connect
    traces=traces
  File "/srv/homeassistant/lib/python3.5/site-packages/aiohttp/connector.py", line 736, in _create_connection
    traces=None
  File "/srv/homeassistant/lib/python3.5/site-packages/aiohttp/connector.py", line 855, in _create_direct_connection
    raise last_exc
  File "/srv/homeassistant/lib/python3.5/site-packages/aiohttp/connector.py", line 838, in _create_direct_connection
    req=req, client_error=client_error)
  File "/srv/homeassistant/lib/python3.5/site-packages/aiohttp/connector.py", line 807, in _wrap_create_connection
    raise client_error(req.connection_key, exc) from exc
aiohttp.client_exceptions.ClientConnectorError: Cannot connect to host 192.168.1.193:8060 ssl:False [Connect call failed ('192.168.1.193', 8060)]
2018-03-18 11:53:50 WARNING (MainThread) [homeassistant.helpers.entity] Update of media_player.roku_2la4d5015997 is taking over 10 seconds
2018-03-18 11:53:51 WARNING (MainThread) [homeassistant.components.media_player] Updating roku media_player took longer than the scheduled update interval 0:00:10
2018-03-18 11:54:02 WARNING (MainThread) [homeassistant.components.media_player] Updating roku media_player took longer than the scheduled update interval 0:00:10
2018-03-18 11:54:13 WARNING (MainThread) [homeassistant.components.media_player] Updating roku media_player took longer than the scheduled update interval 0:00:10
2018-03-18 12:13:56 WARNING (MainThread) [homeassistant.helpers.entity] Update of media_player.roku_2la4d5015997 is taking over 10 seconds
2018-03-18 12:13:57 WARNING (MainThread) [homeassistant.components.media_player] Updating roku media_player took longer than the scheduled update interval 0:00:10
2018-03-18 12:14:08 WARNING (MainThread) [homeassistant.components.media_player] Updating roku media_player took longer than the scheduled update interval 0:00:10
2018-03-18 12:14:19 WARNING (MainThread) [homeassistant.components.media_player] Updating roku media_player took longer than the scheduled update interval 0:00:10
2018-03-18 12:14:30 WARNING (MainThread) [homeassistant.components.media_player] Updating roku media_player took longer than the scheduled update interval 0:00:10
2018-03-18 12:14:41 WARNING (MainThread) [homeassistant.components.media_player] Updating roku media_player took longer than the scheduled update interval 0:00:10
2018-03-18 12:14:52 WARNING (MainThread) [homeassistant.components.media_player] Updating roku media_player took longer than the scheduled update interval 0:00:10
2018-03-18 12:15:03 WARNING (MainThread) [homeassistant.components.media_player] Updating roku media_player took longer than the scheduled update interval 0:00:10
2018-03-18 12:15:14 WARNING (MainThread) [homeassistant.components.media_player] Updating roku media_player took longer than the scheduled update interval 0:00:10
2018-03-18 12:15:25 WARNING (MainThread) [homeassistant.components.media_player] Updating roku media_player took longer than the scheduled update interval 0:00:10
2018-03-18 12:15:36 WARNING (MainThread) [homeassistant.components.media_player] Updating roku media_player took longer than the scheduled update interval 0:00:10
2018-03-18 12:15:47 WARNING (MainThread) [homeassistant.components.media_player] Updating roku media_player took longer than the scheduled update interval 0:00:10
2018-03-18 12:15:58 WARNING (MainThread) [homeassistant.components.media_player] Updating roku media_player took longer than the scheduled update interval 0:00:10
2018-03-18 12:16:09 WARNING (MainThread) [homeassistant.components.media_player] Updating roku media_player took longer than the scheduled update interval 0:00:10
2018-03-18 12:16:20 WARNING (MainThread) [homeassistant.components.media_player] Updating roku media_player took longer than the scheduled update interval 0:00:10
2018-03-18 12:16:31 WARNING (MainThread) [homeassistant.components.media_player] Updating roku media_player took longer than the scheduled update interval 0:00:10
2018-03-18 12:16:42 WARNING (MainThread) [homeassistant.components.media_player] Updating roku media_player took longer than the scheduled update interval 0:00:10
2018-03-18 12:16:53 WARNING (MainThread) [homeassistant.components.media_player] Updating roku media_player took longer than the scheduled update interval 0:00:10
2018-03-18 12:17:04 WARNING (MainThread) [homeassistant.components.media_player] Updating roku media_player took longer than the scheduled update interval 0:00:10
2018-03-18 12:17:15 WARNING (MainThread) [homeassistant.components.media_player] Updating roku media_player took longer than the scheduled update interval 0:00:10
2018-03-18 12:17:26 WARNING (MainThread) [homeassistant.components.media_player] Updating roku media_player took longer than the scheduled update interval 0:00:10
2018-03-18 12:17:37 WARNING (MainThread) [homeassistant.components.media_player] Updating roku media_player took longer than the scheduled update interval 0:00:10
2018-03-18 12:17:48 WARNING (MainThread) [homeassistant.components.media_player] Updating roku media_player took longer than the scheduled update interval 0:00:10
2018-03-18 12:17:59 WARNING (MainThread) [homeassistant.components.media_player] Updating roku media_player took longer than the scheduled update interval 0:00:10
2018-03-18 12:18:10 WARNING (MainThread) [homeassistant.components.media_player] Updating roku media_player took longer than the scheduled update interval 0:00:10
2018-03-18 12:18:21 WARNING (MainThread) [homeassistant.components.media_player] Updating roku media_player took longer than the scheduled update interval 0:00:10
2018-03-18 12:18:32 WARNING (MainThread) [homeassistant.components.media_player] Updating roku media_player took longer than the scheduled update interval 0:00:10
2018-03-18 12:18:43 WARNING (MainThread) [homeassistant.components.media_player] Updating roku media_player took longer than the scheduled update interval 0:00:10
2018-03-18 12:18:54 WARNING (MainThread) [homeassistant.components.media_player] Updating roku media_player took longer than the scheduled update interval 0:00:10
2018-03-18 12:19:05 WARNING (MainThread) [homeassistant.components.media_player] Updating roku media_player took longer than the scheduled update interval 0:00:10
2018-03-18 12:19:16 WARNING (MainThread) [homeassistant.components.media_player] Updating roku media_player took longer than the scheduled update interval 0:00:10
2018-03-18 12:19:27 WARNING (MainThread) [homeassistant.components.media_player] Updating roku media_player took longer than the scheduled update interval 0:00:10
2018-03-18 12:19:38 WARNING (MainThread) [homeassistant.components.media_player] Updating roku media_player took longer than the scheduled update interval 0:00:10
2018-03-18 12:19:49 WARNING (MainThread) [homeassistant.components.media_player] Updating roku media_player took longer than the scheduled update interval 0:00:10
2018-03-18 12:20:00 WARNING (MainThread) [homeassistant.components.media_player] Updating roku media_player took longer than the scheduled update interval 0:00:10
2018-03-18 12:20:11 WARNING (MainThread) [homeassistant.components.media_player] Updating roku media_player took longer than the scheduled update interval 0:00:10
2018-03-18 12:20:22 WARNING (MainThread) [homeassistant.components.media_player] Updating roku media_player took longer than the scheduled update interval 0:00:10
2018-03-18 12:20:33 WARNING (MainThread) [homeassistant.components.media_player] Updating roku media_player took longer than the scheduled update interval 0:00:10
2018-03-18 12:20:44 WARNING (MainThread) [homeassistant.components.media_player] Updating roku media_player took longer than the scheduled update interval 0:00:10
2018-03-18 12:20:55 WARNING (MainThread) [homeassistant.components.media_player] Updating roku media_player took longer than the scheduled update interval 0:00:10
2018-03-18 12:21:06 WARNING (MainThread) [homeassistant.components.media_player] Updating roku media_player took longer than the scheduled update interval 0:00:10
2018-03-18 12:21:17 WARNING (MainThread) [homeassistant.components.media_player] Updating roku media_player took longer than the scheduled update interval 0:00:10
2018-03-18 12:21:28 WARNING (MainThread) [homeassistant.components.media_player] Updating roku media_player took longer than the scheduled update interval 0:00:10
2018-03-18 12:21:39 WARNING (MainThread) [homeassistant.components.media_player] Updating roku media_player took longer than the scheduled update interval 0:00:10
2018-03-18 12:21:50 WARNING (MainThread) [homeassistant.components.media_player] Updating roku media_player took longer than the scheduled update interval 0:00:10
2018-03-18 12:22:01 WARNING (MainThread) [homeassistant.components.media_player] Updating roku media_player took longer than the scheduled update interval 0:00:10
2018-03-18 12:22:12 WARNING (MainThread) [homeassistant.components.media_player] Updating roku media_player took longer than the scheduled update interval 0:00:10
2018-03-18 12:22:23 WARNING (MainThread) [homeassistant.components.media_player] Updating roku media_player took longer than the scheduled update interval 0:00:10
2018-03-18 12:22:34 WARNING (MainThread) [homeassistant.components.media_player] Updating roku media_player took longer than the scheduled update interval 0:00:10
2018-03-18 12:22:45 WARNING (MainThread) [homeassistant.components.media_player] Updating roku media_player took longer than the scheduled update interval 0:00:10
2018-03-18 12:22:56 WARNING (MainThread) [homeassistant.components.media_player] Updating roku media_player took longer than the scheduled update interval 0:00:10
2018-03-18 12:23:07 WARNING (MainThread) [homeassistant.components.media_player] Updating roku media_player took longer than the scheduled update interval 0:00:10
2018-03-18 12:23:18 WARNING (MainThread) [homeassistant.components.media_player] Updating roku media_player took longer than the scheduled update interval 0:00:10
2018-03-18 12:23:29 WARNING (MainThread) [homeassistant.components.media_player] Updating roku media_player took longer than the scheduled update interval 0:00:10
2018-03-18 12:23:40 WARNING (MainThread) [homeassistant.components.media_player] Updating roku media_player took longer than the scheduled update interval 0:00:10
2018-03-18 12:23:51 WARNING (MainThread) [homeassistant.components.media_player] Updating roku media_player took longer than the scheduled update interval 0:00:10
2018-03-18 12:24:02 WARNING (MainThread) [homeassistant.components.media_player] Updating roku media_player took longer than the scheduled update interval 0:00:10
2018-03-18 12:24:13 WARNING (MainThread) [homeassistant.components.media_player] Updating roku media_player took longer than the scheduled update interval 0:00:10
2018-03-18 12:24:24 WARNING (MainThread) [homeassistant.components.media_player] Updating roku media_player took longer than the scheduled update interval 0:00:10
2018-03-18 12:24:35 WARNING (MainThread) [homeassistant.components.media_player] Updating roku media_player took longer than the scheduled update interval 0:00:10
2018-03-18 12:24:46 WARNING (MainThread) [homeassistant.components.media_player] Updating roku media_player took longer than the scheduled update interval 0:00:10
2018-03-18 12:24:57 WARNING (MainThread) [homeassistant.components.media_player] Updating roku media_player took longer than the scheduled update interval 0:00:10
2018-03-18 12:25:08 WARNING (MainThread) [homeassistant.components.media_player] Updating roku media_player took longer than the scheduled update interval 0:00:10
2018-03-18 12:25:19 WARNING (MainThread) [homeassistant.components.media_player] Updating roku media_player took longer than the scheduled update interval 0:00:10
2018-03-18 12:25:30 WARNING (MainThread) [homeassistant.components.media_player] Updating roku media_player took longer than the scheduled update interval 0:00:10
2018-03-18 12:25:41 WARNING (MainThread) [homeassistant.components.media_player] Updating roku media_player took longer than the scheduled update interval 0:00:10
2018-03-18 12:25:52 WARNING (MainThread) [homeassistant.components.media_player] Updating roku media_player took longer than the scheduled update interval 0:00:10
2018-03-18 12:26:03 WARNING (MainThread) [homeassistant.components.media_player] Updating roku media_player took longer than the scheduled update interval 0:00:10
2018-03-18 12:26:14 WARNING (MainThread) [homeassistant.components.media_player] Updating roku media_player took longer than the scheduled update interval 0:00:10
2018-03-18 12:26:25 WARNING (MainThread) [homeassistant.components.media_player] Updating roku media_player took longer than the scheduled update interval 0:00:10
2018-03-18 12:26:36 WARNING (MainThread) [homeassistant.components.media_player] Updating roku media_player took longer than the scheduled update interval 0:00:10
2018-03-18 12:26:47 WARNING (MainThread) [homeassistant.components.media_player] Updating roku media_player took longer than the scheduled update interval 0:00:10
2018-03-18 12:26:58 WARNING (MainThread) [homeassistant.components.media_player] Updating roku media_player took longer than the scheduled update interval 0:00:10
2018-03-18 12:27:09 WARNING (MainThread) [homeassistant.components.media_player] Updating roku media_player took longer than the scheduled update interval 0:00:10
2018-03-18 12:27:20 WARNING (MainThread) [homeassistant.components.media_player] Updating roku media_player took longer than the scheduled update interval 0:00:10
2018-03-18 12:27:31 WARNING (MainThread) [homeassistant.components.media_player] Updating roku media_player took longer than the scheduled update interval 0:00:10
2018-03-18 12:27:42 WARNING (MainThread) [homeassistant.components.media_player] Updating roku media_player took longer than the scheduled update interval 0:00:10
2018-03-18 12:27:53 WARNING (MainThread) [homeassistant.components.media_player] Updating roku media_player took longer than the scheduled update interval 0:00:10
2018-03-18 12:28:04 WARNING (MainThread) [homeassistant.components.media_player] Updating roku media_player took longer than the scheduled update interval 0:00:10
2018-03-18 12:28:15 WARNING (MainThread) [homeassistant.components.media_player] Updating roku media_player took longer than the scheduled update interval 0:00:10
2018-03-18 12:28:26 WARNING (MainThread) [homeassistant.components.media_player] Updating roku media_player took longer than the scheduled update interval 0:00:10
2018-03-18 12:28:37 WARNING (MainThread) [homeassistant.components.media_player] Updating roku media_player took longer than the scheduled update interval 0:00:10
2018-03-18 12:28:48 WARNING (MainThread) [homeassistant.components.media_player] Updating roku media_player took longer than the scheduled update interval 0:00:10
2018-03-18 12:28:59 WARNING (MainThread) [homeassistant.components.media_player] Updating roku media_player took longer than the scheduled update interval 0:00:10
2018-03-18 12:29:10 WARNING (MainThread) [homeassistant.components.media_player] Updating roku media_player took longer than the scheduled update interval 0:00:10
2018-03-18 12:29:21 WARNING (MainThread) [homeassistant.components.media_player] Updating roku media_player took longer than the scheduled update interval 0:00:10
2018-03-18 12:29:31 WARNING (MainThread) [homeassistant.components.media_player] Updating roku media_player took longer than the scheduled update interval 0:00:10
2018-03-18 12:29:42 WARNING (MainThread) [homeassistant.components.media_player] Updating roku media_player took longer than the scheduled update interval 0:00:10
2018-03-18 12:29:53 WARNING (MainThread) [homeassistant.components.media_player] Updating roku media_player took longer than the scheduled update interval 0:00:10
2018-03-18 12:30:04 WARNING (MainThread) [homeassistant.components.media_player] Updating roku media_player took longer than the scheduled update interval 0:00:10
2018-03-18 12:30:15 WARNING (MainThread) [homeassistant.components.media_player] Updating roku media_player took longer than the scheduled update interval 0:00:10
2018-03-18 12:30:26 WARNING (MainThread) [homeassistant.components.media_player] Updating roku media_player took longer than the scheduled update interval 0:00:10
2018-03-18 12:30:37 WARNING (MainThread) [homeassistant.components.media_player] Updating roku media_player took longer than the scheduled update interval 0:00:10
2018-03-18 12:30:48 WARNING (MainThread) [homeassistant.components.media_player] Updating roku media_player took longer than the scheduled update interval 0:00:10
2018-03-18 12:30:59 WARNING (MainThread) [homeassistant.components.media_player] Updating roku media_player took longer than the scheduled update interval 0:00:10
